Workbook

Sheet 요약
B1: 하카타 항로 손익분석 — 근거 요약
B2: 대저페리 감사보고서(제3기·2024) 손익계산서를 원본 그대로 싣고, 1인당 인건비·지급수수료·목표 영업이익률 분석을 얹는다. 대조 선박은 산타모니카호를 하카타 항로에 투입한다는 가정.
B4: 지표 | C4: 참조 · 실적 2024 (대저페리 3기) | D4: 대조 선박 (하카타 투입 가정) | E4: 산식 · 근거 시트
B5: 영업손익 (원) | C5: =원가구조_기준!$C$13 -> -2079522109 | D5: =대조선박_손익!$C$87 -> 5.2085192e+09 | E5: 참조: 손익계산서_원본 Ⅴ · 대조: 대조선박_손익 Ⅴ
B6: 영업이익률 | C6: =원가구조_기준!$C$13/원가구조_기준!$C$7 -> -0.15817935 | D6: =대조선박_손익!$C$97 -> 0.22645462
B7: EBITDA (원) | C7: =원가구조_기준!$C$15 -> 1269709891 | D7: =대조선박_손익!$C$88 -> 5.2085192e+09 | E7: 영업이익 + 감가상각비
B8: EBITDA 마진 | C8: =원가구조_기준!$C$15/원가구조_기준!$C$7 -> 0.096580789 | D8: =대조선박_손익!$C$88/대조선박_손익!$C$48 -> 0.22645462
B9: 1인당 인건비 — 현금 (원/년) | C9: =인건비_부가가치!$C$29 -> 65681069 | D9: =인건비_부가가치!$D$29 -> 69835421 | E9: 인건비_부가가치 3 · 대조는 지상직+해상직 전사 기준
B10: + 퇴직 (비현금) 1인당 | C10: =인건비_부가가치!$C$31 -> 5080673.1 | D10: =인건비_부가가치!$D$31 -> 6013443.9
B11: 합계 1인당 | C11: =인건비_부가가치!$C$32 -> 70761742 | D11: =인건비_부가가치!$D$32 -> 75848865
B12: 손익분기 승객수 (명) | C12: =목표이익률_지표!$C$35 -> 168466.82 | D12: =목표이익률_지표!$C$81 -> 136993.92 | E12: 목표이익률_지표 0% 행
B13: 비교 기준 승객수 | C13: =원가구조_기준!$C$45 -> 144058.09 | D13: =대조선박_손익!$C$25 -> 181800 | E13: 참조: 실적 역산 · 대조: 승선율 기반 현재 설정
B14: 차이 | C14: =IFERROR(C12-C13,"") -> 24408.734 | D14: =IFERROR(D12-D13,"") -> -44806.078
B15: 손익분기 승선율 | C15: =IFERROR(목표이익률_지표!$C$35/(원가구조_기준!$C$47*설정값!$D$11),"") -> 0.34874927 | D15: =IFERROR(목표이익률_지표!$C$81/(대조선박_손익!$C$7*설정값!$D$43),"") -> 0.37677096 | E15: 승객수 ÷ (정원 × 항차)
B16: 목표 달성 승객수 (명) | C16: =목표이익률_지표!$C$41 -> 200443.98 | D16: =목표이익률_지표!$C$87 -> 163901.25 | E16: 목표이익률_지표 설정 목표 행
B17: 목표 영업이익률 | C17: =설정값!$D$19 -> 0.15 | D17: =설정값!$D$44 -> 0.15 | E17: 설정값
B18: 항차당 승객 | C18: =IFERROR(목표이익률_지표!$C$41/설정값!$D$11,"") -> 402.49795 | D18: =IFERROR(목표이익률_지표!$C$87/설정값!$D$43,"") -> 273.16875
B19: 목표 승선율 | C19: =IFERROR(목표이익률_지표!$C$41/(원가구조_기준!$C$47*설정값!$D$11),"") -> 0.41494634 | D19: =IFERROR(목표이익률_지표!$C$87/(대조선박_손익!$C$7*설정값!$D$43),"") -> 0.45077351
B20: 가동율 (편도항차 ÷ 730) | C20: =설정값!$D$11/설정값!$D$91 -> 0.68219178 | D20: =설정값!$D$43/설정값!$D$91 -> 0.82191781
B21: 연간 편도 항차 | C21: =설정값!$D$11 -> 498 | D21: =설정값!$D$43 -> 600
B22: 실현 단가 (원/인) | C22: =원가구조_기준!$C$44 -> 88950 | D22: =대조선박_손익!$C$23 -> 120000 | E22: 가중평균 운임 + 유류할증료
B23: 매출액 (원) | C23: =원가구조_기준!$C$7 -> 13146609166 | D23: =대조선박_손익!$C$48 -> 23000277600
B24: 부채상환커버리지비율 DSCR (CFADS ÷ 거치 후 원리금) | C24: - | D24: =대조선박_손익!$C$104 -> 1.6231147 | E24: 대조선박_손익 6 — 분자 CFADS = EBITDA − 법인세 − 우발수리유보금 − 선박대체유보금
B25: 10개년 평균 영업이익 (백만원) | C25: - | D25: ='10개년_예상'!$O$48 -> 6061.6083 | E25: 선체이자 운항원가 반영 기준
B26: 대조 선박 분석 상태 | C26: - | D26: =대조선박_손익!$C$8 -> 분석 가능
B27: 검산 결과 | C27: =검산!$F$32 -> 24 / 26 OK | E27: 검산 시트 — 주석 7 퇴직급여충당부채 전입액은 보고서 자체 차이 1,193원 (도 ⚠ 표시)
B29: 시트 안내
B30: 설정값 | C30: 모든 가정·입력 (주황 칸) + 10개년 성장률 + 고정 상수
B31: 손익계산서_원본 | C31: 대저페리 제3기 감사보고서 손익계산서 (당기·전기) + 주석 15 운항원가 세부 + EBITDA 조정
B32: 주석_보조자료 | C32: 주석 15 부가가치 관련자료(천원) · 주석 7 · 현금흐름표 · 부가세예수금
B33: 원가구조_기준 | C33: 감사보고서 파생값 · 1인당 인건비 · 실현 단가/역산 승객수 · 운항기타 세목 · 고정/준변동/변동 분해
B34: 대조선박_손익 | C34: 대조 선박 스케일 규칙 · 운항기타 산출 근거 · 단일연도 손익계산서 · 수지 · DSCR
B35: 차입금_상환 | C35: 차입 조건 · 첫해 원리금 · 40년 상환 스케줄 (선체이자 근거)
B36: 10개년_예상 | C36: 대조 선박 10개년 예상 손익 (백만원) — 성장률 × 복리, 선체이자는 스케줄
B37: 목표이익률_지표 | C37: 손익분기·목표 승객수, 필요 운임, 원가 비중 — 참조·대조 (항차 자동증가 반복계산 포함)
B38: CVP_손익분기 | C38: 승객수별 매출·총비용 표와 차트
B39: 인건비_부가가치 | C39: 1인당 분해 · 지상/해상 분리 · 부가가치 · 부가세 역산 가능성 · 지급수수료
B40: 운임_화물_선박 | C40: 대저페리 운임표 · 좌석 배율 · 선박 제원 · 차량 운임표 · 적재 케이스
B41: 검산 | C41: 보고서 기재값 대조 · 계산 경로 일치 검증
B42: 출처_한계 | C42: 자료 출처 · 분석의 한계 · 용어

Sheet 설정값
B1: 설정값 — 모든 가정·입력을 한 곳에
B2: 주황 바탕 칸만 바꾸면 모든 시트가 따라 움직인다. 기본값 = 화면의 기본값(감사보고서 기준안).
B4: 범례 | C4: 입력 (바꿔도 되는 칸) | D4: 고정 상수 | E4: 계산 | F4: O/X · 성격 · 상환방식 · 선박 · 케이스 칸은 드롭다운
B6: A. 기준 자료 — 참조 선박 (대저페리 제3기 · 2024 · 엘도라도 익스프레스호)
B7: 그룹 | C7: 항목 | D7: 값 | E7: 단위 | F7: 근거 · 비고
B8: 인력 | C8: 지상직 (판관비) | D8: 30 | E8: 명 | F8: 판관비 급여영역(직원급여·퇴직급여·복리후생비)을 나누는 인원
C9: 선원 | D9: 13 | E9: 명 | F9: 가정 — 보고서에 인원 없음. 운항원가 인건비 1인당 산출에만 사용
C10: 승무원 | D10: 7 | E10: 명 | F10: 가정 — 보고서에 인원 없음
C11: 연간 편도 항차수 | D11: 498 | E11: 항차 | F11: 울릉크루즈 보도자료 연간 운항 실적 https://www.ulcruise.co.kr/www/aboutus/press?mode=view&idx=5807
B12: 운임 | C12: 이코노미 대인 운임 (기준) | D12: 81000 | E12: 원 | F12: 대저페리 공시 운임표 대인 이코노미 정상
C13: 유류할증료 | D13: 7950 | E13: 원/인 | F13: 미공시 — 가정. 회계상 여객수입에 포함되므로 실현 단가에 더한다
C14: 좌석 구성비 — 이코노미 | D14: 1 | E14: % | F14: 보고서에 없어 입력값. 합이 100%가 아니면 정규화
C15: 좌석 구성비 — 비즈니스 | D15: 0 | E15: % | F15: 배율 1.5 (공시 운임)
C16: 좌석 구성비 — 퍼스트 | D16: 0 | E16: % | F16: 배율 2.1173 (공시 운임)
B17: 원가 | C17: 승객 1인당 추가 변동비 | D17: 0 | E17: 원/인 | F17: 원가 구성표에 없는 몫을 손으로 얹는 칸
C18: 승객이 정원을 넘으면 항차를 늘린다 | D18: X | E18: O/X | F18: 준변동비는 승객이 아니라 항차에 붙는다. O면 필요 항차 = MAX(설정 항차, ⌈승객수÷정원⌉)
B19: 목표 | C19: 목표 영업이익률 | D19: 0.15 | E19: % | F19: 참조(감사보고서 구조) 탭의 목표
B20: 승객 | C20: 시뮬레이션 연간 승객수 | E20: 명 | F20: 비워 두면 실적 역산값 144,058명 (여객수입 ÷ 실현단가 88,950원 = 이코노미 81,000 + 유류할증 7,950). 화면도 같은 식으로 열린다.
B21: A-2. 운항기타 세목 비율 (가정) — 감사보고서 잔액 7,148,774,749원을 나누는 비율
B22: 그룹 | C22: 세목 | D22: 비율 | E22: 단위 | F22: 기본 비율의 근거
B23: 운항비 | C23: 연료비 | D23: 0.8345 | E23: % | F23: 820$/MT · 편도 217km × 49.5kg/km · 500항차 역산 → 5,989,460,400원 · 항차에 붙는다
B24: 운항비 | C24: 항비 | D24: 0.1115 | E24: % | F24: 입출항료·접안료·도선료·터미널 — 나머지 넷을 뺀 잔액
B25: 선비 | C25: 보험료 | D25: 0.0513 | E25: % | F25: 주석 4 선박보험 부보액 73,378,500천원 × 0.5% (통상 요율) · P&I 별도
B26: 선비 | C26: 수리비 | D26: 0 | E26: % | F26: 단일연도는 0 — 선령이 낮아 보증기간·보험금 청구로 처리(판관비 수선비도 당기 0원). 10개년에는 아래 E 섹션의 10년 수리비(첫해 700백만 · 연 5%)가 따로 들어간다.
B27: 선비 | C27: 선용품비 | D27: 0.0027 | E27: % | F27: 윤활유·소모품 — 저장품 감소분 53,922,777 → 34,438,118 (19,484,659원)
B28: A-3. 원가 항목의 포함 여부 · 성격 (고정 · 준변동 · 변동)
B29: 손익계산서 소속 | C29: 원가 항목 | D29: 계산에 포함 | E29: 성격 | F29: 비고
B30: 운항원가 | C30: 운항 인건비 (급여·퇴직·복리) | D30: O | E30: 고정 | F30: 선원+승무원 · 승객수 무관
B31: 운항원가 | C31: 운항 감가상각비 | D31: O | E31: 고정 | F31: 선가 ÷ 내용연수 정액 · 비현금 · 포함을 X로 두면 EBITDA 기준
B32: 운항원가 | C32: 운항 세금과공과·임차료 | D32: O | E32: 고정
B33: 운항원가 | C33: 운항기타 (항비·연료비·잡비) | D33: O | E33: 준변동 | F33: 운항원가의 58% · 항차 연동
B34: 판매비와관리비 | C34: 판관 급여영역 | D34: O | E34: 고정 | F34: 직원 수 연동 · 승객수 무관
B35: 판매비와관리비 | C35: 판관 그 밖 13과목 | D35: O | E35: 고정
B36: 판매비와관리비 | C36: 지급수수료 | D36: O | E36: 변동 | F36: 예약·결제 수수료 · 승객 연동
B37: B. 대조 선박 설정 — 하카타 항로 투입 시나리오
B38: 그룹 | C38: 항목 | D38: 값 | E38: 단위 | F38: 근거 · 비고
B39: 선박 | C39: 대조 선박 | D39: 산타모니카호 | F39: 목록: 산타모니카호 · 퀸비틀(보류) · 코리아프라이드호(보류). 정원은 운임_화물_선박 시트에서 찾는다
B40: 인력 | C40: 지상직 (판관비) | D40: 30 | E40: 명 | F40: 판관 급여 3과목 = 감사보고서 × (지상직 ÷ 30명)
C41: 선원 | D41: 13 | E41: 명 | F41: 가정 — 운항 인건비 = 감사보고서 × (대조 해상직 ÷ 참조 해상직)
C42: 승무원 | D42: 7 | E42: 명 | F42: 가정
...

Sheet 손익계산서_원본
B1: 손익계산서 — 주식회사 대저페리 제3기 (2024.01.01 ~ 2024.12.31) 감사보고서 원본
B2: (단위: 원) · 제2기(2023)는 감사받지 아니한 수치 · [주석15]/[차액]/[가정치]/[보완] 행은 보고서 손익계산서 지면에는 없는 행
B4: 구분 | C4: 과 목 | D4: 제3(당)기 2024 | E4: 구성비 | F4: 매출 대비 | G4: 제2(전)기 2023 | H4: 구성비 | I4: 매출 대비 | J4: 증감 | K4: 비고 · 출처
B5: 항목 | C5: Ⅰ.매출액 | D5: =SUM(D6:D9) -> 13146609166 | F5: =IF(D5="","",D5/D$5) -> 1 | G5: =SUM(G6:G9) -> 5596485400 | I5: =IF(G5="","",G5/G$5) -> 1 | J5: =IF(OR(D5="",G5=""),"",D5-G5) -> 7550123766 | K5: 보고서 13,146,609,166
B6: 세부 | C6: 여객수입 | D6: 12813966995 | E6: =IF(OR(D6="",D5=0),"",D6/D5) -> 0.97469749 | F6: =IF(D6="","",D6/D$5) -> 0.97469749 | G6: 5527657183 | H6: =IF(OR(G6="",G5=0),"",G6/G5) -> 0.98770153 | I6: =IF(G6="","",G6/G$5) -> 0.98770153 | J6: =IF(OR(D6="",G6=""),"",D6-G6) -> 7286309812
B7: 세부 | C7: 화물수입 | D7: 323042171 | E7: =IF(OR(D7="",D5=0),"",D7/D5) -> 0.024572281 | F7: =IF(D7="","",D7/D$5) -> 0.024572281 | G7: 52186526 | H7: =IF(OR(G7="",G5=0),"",G7/G5) -> 0.0093248749 | I7: =IF(G7="","",G7/G$5) -> 0.0093248749 | J7: =IF(OR(D7="",G7=""),"",D7-G7) -> 270855645
B8: 세부 | C8: 임대료수입 | D8: 9600000 | E8: =IF(OR(D8="",D5=0),"",D8/D5) -> 0.00073022632 | F8: =IF(D8="","",D8/D$5) -> 0.00073022632 | G8: 5732600 | H8: =IF(OR(G8="",G5=0),"",G8/G5) -> 0.0010243214 | I8: =IF(G8="","",G8/G$5) -> 0.0010243214 | J8: =IF(OR(D8="",G8=""),"",D8-G8) -> 3867400
B9: 세부 | C9: 기타수입 | E9: =IF(OR(D9="",D5=0),"",D9/D5) | F9: =IF(D9="","",D9/D$5) | G9: 10909091 | H9: =IF(OR(G9="",G5=0),"",G9/G5) -> 0.0019492753 | I9: =IF(G9="","",G9/G$5) -> 0.0019492753 | J9: =IF(OR(D9="",G9=""),"",D9-G9)
B10: 항목 | C10: Ⅱ.매출원가 | D10: =D11 -> 12246808749 | F10: =IF(D10="","",D10/D$5) -> 0.93155646 | G10: =G11 -> 6725627421 | I10: =IF(G10="","",G10/G$5) -> 1.2017591 | J10: =IF(OR(D10="",G10=""),"",D10-G10) -> 5521181328 | K10: 보고서 12,246,808,749
B11: 세부 | C11: 운항원가 | D11: 12246808749 | E11: =IF(OR(D11="",D10=0),"",D11/D10) -> 1 | F11: =IF(D11="","",D11/D$5) -> 0.93155646 | G11: 6725627421 | H11: =IF(OR(G11="",G10=0),"",G11/G10) -> 1 | I11: =IF(G11="","",G11/G$5) -> 1.2017591 | J11: =IF(OR(D11="",G11=""),"",D11-G11) -> 5521181328
B12: 주석15 | C12: 급여 | D12: =주석_보조자료!$D$6*1000 -> 1253988000 | E12: =IF(OR(D12="",D10=0),"",D12/D10) -> 0.10239304 | F12: =IF(D12="","",D12/D$5) -> 0.0953849 | G12: =IF(주석_보조자료!$G$6=0,"",주석_보조자료!$G$6*1000) -> 598243000 | H12: =IF(OR(G12="",G10=0),"",G12/G10) -> 0.088949768 | I12: =IF(G12="","",G12/G$5) -> 0.1068962 | J12: =IF(OR(D12="",G12=""),"",D12-G12) -> 655745000 | K12: [주석15] 운항원가 열 × 1,000
B13: 주석15 | C13: 퇴직급여 | D13: =주석_보조자료!$D$7*1000 -> 148252000 | E13: =IF(OR(D13="",D10=0),"",D13/D10) -> 0.012105358 | F13: =IF(D13="","",D13/D$5) -> 0.011276824 | G13: =IF(주석_보조자료!$G$7=0,"",주석_보조자료!$G$7*1000) -> 21645000 | H13: =IF(OR(G13="",G10=0),"",G13/G10) -> 0.0032182871 | I13: =IF(G13="","",G13/G$5) -> 0.0038676059 | J13: =IF(OR(D13="",G13=""),"",D13-G13) -> 126607000 | K13: [주석15]
B14: 주석15 | C14: 복리후생비 | D14: =주석_보조자료!$D$8*1000 -> 267351000 | E14: =IF(OR(D14="",D10=0),"",D14/D10) -> 0.021830258 | F14: =IF(D14="","",D14/D$5) -> 0.020336118 | G14: =IF(주석_보조자료!$G$8=0,"",주석_보조자료!$G$8*1000) -> 122501000 | H14: =IF(OR(G14="",G10=0),"",G14/G10) -> 0.018214063 | I14: =IF(G14="","",G14/G$5) -> 0.021888916 | J14: =IF(OR(D14="",G14=""),"",D14-G14) -> 144850000 | K14: [주석15]
B15: 주석15 | C15: 감가상각비 | D15: =주석_보조자료!$D$10*1000 -> 3349232000 | E15: =IF(OR(D15="",D10=0),"",D15/D10) -> 0.27347794 | F15: =IF(D15="","",D15/D$5) -> 0.25476014 | G15: =IF(주석_보조자료!$G$10=0,"",주석_보조자료!$G$10*1000) -> 1665933000 | H15: =IF(OR(G15="",G10=0),"",G15/G10) -> 0.24769927 | I15: =IF(G15="","",G15/G$5) -> 0.29767486 | J15: =IF(OR(D15="",G15=""),"",D15-G15) -> 1683299000 | K15: [주석15] 선가 670억 · 20년 정액
B16: 주석15 | C16: 세금과공과 | D16: =주석_보조자료!$D$11*1000 -> 48282000 | E16: =IF(OR(D16="",D10=0),"",D16/D10) -> 0.0039424148 | F16: =IF(D16="","",D16/D$5) -> 0.003672582 | G16: =IF(주석_보조자료!$G$11=0,"",주석_보조자료!$G$11*1000) -> 67295000 | H16: =IF(OR(G16="",G10=0),"",G16/G10) -> 0.010005758 | I16: =IF(G16="","",G16/G$5) -> 0.012024511 | J16: =IF(OR(D16="",G16=""),"",D16-G16) -> -19013000 | K16: [주석15]
B17: 주석15 | C17: 임차료 | D17: =주석_보조자료!$D$12*1000 -> 30929000 | E17: =IF(OR(D17="",D10=0),"",D17/D10) -> 0.0025254742 | F17: =IF(D17="","",D17/D$5) -> 0.0023526219 | G17: =IF(주석_보조자료!$G$12=0,"",주석_보조자료!$G$12*1000) | H17: =IF(OR(G17="",G10=0),"",G17/G10) | I17: =IF(G17="","",G17/G$5) | J17: =IF(OR(D17="",G17=""),"",D17-G17) | K17: [주석15] 전기 "-"
B18: 주석15 | C18: 운항기타(항비,연료비,기타 잡비) | D18: =D11-SUM(D12:D17) -> 7148774749 | E18: =IF(OR(D18="",D10=0),"",D18/D10) -> 0.58372552 | F18: =IF(D18="","",D18/D$5) -> 0.54377328 | G18: =G11-SUM(G12:G17) -> 4250010421 | H18: =IF(OR(G18="",G10=0),"",G18/G10) -> 0.63191285 | I18: =IF(G18="","",G18/G$5) -> 0.75940704 | J18: =IF(OR(D18="",G18=""),"",D18-G18) -> 2898764328 | K18: [차액] 운항원가 − 위 6줄 (반올림 흡수)
B19: 가정치 | C19: · 연료비 | D19: =IFERROR(D18*설정값!$D$23/(설정값!$D$23+설정값!$D$24+설정값!$D$25+설정값!$D$26+설정값!$D$27),0) -> 5.9656525e+09 | E19: =IF(OR(D19="",D10=0),"",D19/D10) -> 0.48711894 | F19: =IF(D19="","",D19/D$5) -> 0.4537788 | K19: [가정치] 운항기타 × 세목 비율 (설정값 A-2)
B20: 가정치 | C20: · 항비 | D20: =IFERROR(D18*설정값!$D$24/(설정값!$D$23+설정값!$D$24+설정값!$D$25+설정값!$D$26+설정값!$D$27),0) -> 7.9708838e+08 | E20: =IF(OR(D20="",D10=0),"",D20/D10) -> 0.065085395 | F20: =IF(D20="","",D20/D$5) -> 0.06063072 | K20: [가정치]
B21: 가정치 | C21: · 보험료 | D21: =IFERROR(D18*설정값!$D$25/(설정값!$D$23+설정값!$D$24+설정값!$D$25+설정값!$D$26+설정값!$D$27),0) -> 3.6673214e+08 | E21: =IF(OR(D21="",D10=0),"",D21/D10) -> 0.029945119 | F21: =IF(D21="","",D21/D$5) -> 0.027895569 | K21: [가정치]
B22: 가정치 | C22: · 수리비 | D22: =IFERROR(D18*설정값!$D$26/(설정값!$D$23+설정값!$D$24+설정값!$D$25+설정값!$D$26+설정값!$D$27),0) -> 0 | E22: =IF(OR(D22="",D10=0),"",D22/D10) -> 0 | F22: =IF(D22="","",D22/D$5) -> 0 | K22: [가정치]
B23: 가정치 | C23: · 선용품비 | D23: =IFERROR(D18*설정값!$D$27/(설정값!$D$23+설정값!$D$24+설정값!$D$25+설정값!$D$26+설정값!$D$27),0) -> 19301692 | E23: =IF(OR(D23="",D10=0),"",D23/D10) -> 0.0015760589 | F23: =IF(D23="","",D23/D$5) -> 0.0014681878 | K23: [가정치]
B24: 소계 | C24: Ⅲ.매출총이익(손실) | D24: =D5-D10 -> 899800417 | F24: =IF(D24="","",D24/D$5) -> 0.068443536 | G24: =G5-G10 -> -1129142021 | I24: =IF(G24="","",G24/G$5) -> -0.20175913 | J24: =IF(OR(D24="",G24=""),"",D24-G24) -> 2028942438 | K24: 보고서 899,800,417
B25: 항목 | C25: Ⅳ.판매비와관리비(주15) | D25: =SUM(D26:D44) -> 2979322526 | F25: =IF(D25="","",D25/D$5) -> 0.22662289 | G25: =SUM(G26:G44) -> 2319581793 | I25: =IF(G25="","",G25/G$5) -> 0.41447116 | J25: =IF(OR(D25="",G25=""),"",D25-G25) -> 659740733 | K25: 보고서 2,979,322,526
B26: 세부 | C26: 직원급여 | D26: 1822878650 | E26: =IF(OR(D26="",D25=0),"",D26/D25) -> 0.61184334 | F26: =IF(D26="","",D26/D$5) -> 0.1386577 | G26: 925393401 | H26: =IF(OR(G26="",G25=0),"",G26/G25) -> 0.39894838 | I26: =IF(G26="","",G26/G$5) -> 0.1653526 | J26: =IF(OR(D26="",G26=""),"",D26-G26) -> 897485249
B27: 세부 | C27: 퇴직급여 | D27: 152420193 | E27: =IF(OR(D27="",D25=0),"",D27/D25) -> 0.051159346 | F27: =IF(D27="","",D27/D$5) -> 0.011593879 | G27: 47090190 | H27: =IF(OR(G27="",G25=0),"",G27/G25) -> 0.020301155 | I27: =IF(G27="","",G27/G$5) -> 0.0084142433 | J27: =IF(OR(D27="",G27=""),"",D27-G27) -> 105330003
B28: 세부 | C28: 복리후생비 | D28: 147553407 | E28: =IF(OR(D28="",D25=0),"",D28/D25) -> 0.049525825 | F28: =IF(D28="","",D28/D$5) -> 0.011223686 | G28: 149856057 | H28: =IF(OR(G28="",G25=0),"",G28/G25) -> 0.064604774 | I28: =IF(G28="","",G28/G$5) -> 0.026776815 | J28: =IF(OR(D28="",G28=""),"",D28-G28) -> -2302650
B29: 세부 | C29: 여비교통비 | D29: 9246562 | E29: =IF(OR(D29="",D25=0),"",D29/D25) -> 0.0031035787 | F29: =IF(D29="","",D29/D$5) -> 0.00070334197 | G29: 13978890 | H29: =IF(OR(G29="",G25=0),"",G29/G25) -> 0.00602647 | I29: =IF(G29="","",G29/G$5) -> 0.002497798 | J29: =IF(OR(D29="",G29=""),"",D29-G29) -> -4732328
B30: 세부 | C30: 접대비 | D30: 8802000 | E30: =IF(OR(D30="",D25=0),"",D30/D25) -> 0.0029543629 | F30: =IF(D30="","",D30/D$5) -> 0.00066952625 | G30: 4574200 | H30: =IF(OR(G30="",G25=0),"",G30/G25) -> 0.0019719934 | I30: =IF(G30="","",G30/G$5) -> 0.00081733439 | J30: =IF(OR(D30="",G30=""),"",D30-G30) -> 4227800
B31: 세부 | C31: 통신비 | D31: 9364469 | E31: =IF(OR(D31="",D25=0),"",D31/D25) -> 0.0031431538 | F31: =IF(D31="","",D31/D$5) -> 0.0007123106 | G31: 1820713 | H31: =IF(OR(G31="",G25=0),"",G31/G25) -> 0.00078493158 | I31: =IF(G31="","",G31/G$5) -> 0.0003253315 | J31: =IF(OR(D31="",G31=""),"",D31-G31) -> 7543756
B32: 세부 | C32: 수도광열비 | D32: 16446116 | E32: =IF(OR(D32="",D25=0),"",D32/D25) -> 0.0055200858 | F32: =IF(D32="","",D32/D$5) -> 0.0012509778 | G32: 5716101 | H32: =IF(OR(G32="",G25=0),"",G32/G25) -> 0.0024642809 | I32: =IF(G32="","",G32/G$5) -> 0.0010213733 | J32: =IF(OR(D32="",G32=""),"",D32-G32) -> 10730015
B33: 세부 | C33: 세금과공과 | D33: 62971500 | E33: =IF(OR(D33="",D25=0),"",D33/D25) -> 0.021136181 | F33: =IF(D33="","",D33/D$5) -> 0.0047899423 | G33: 28336468 | H33: =IF(OR(G33="",G25=0),"",G33/G25) -> 0.012216197 | I33: =IF(G33="","",G33/G$5) -> 0.0050632613 | J33: =IF(OR(D33="",G33=""),"",D33-G33) -> 34635032
B34: 세부 | C34: 지급임차료 | D34: 74136257 | E34: =IF(OR(D34="",D25=0),"",D34/D25) -> 0.024883596 | F34: =IF(D34="","",D34/D$5) -> 0.0056391923 | G34: 29850264 | H34: =IF(OR(G34="",G25=0),"",G34/G25) -> 0.012868813 | I34: =IF(G34="","",G34/G$5) -> 0.0053337518 | J34: =IF(OR(D34="",G34=""),"",D34-G34) -> 44285993
B35: 세부 | C35: 수선비 | E35: =IF(OR(D35="",D25=0),"",D35/D25) | F35: =IF(D35="","",D35/D$5) | G35: 5262727 | H35: =IF(OR(G35="",G25=0),"",G35/G25) -> 0.0022688258 | I35: =IF(G35="","",G35/G$5) -> 0.00094036286 | J35: =IF(OR(D35="",G35=""),"",D35-G35)
B36: 세부 | C36: 보험료 | D36: 7359767 | E36: =IF(OR(D36="",D25=0),"",D36/D25) -> 0.0024702821 | F36: =IF(D36="","",D36/D$5) -> 0.00055982245 | G36: 5509172 | H36: =IF(OR(G36="",G25=0),"",G36/G25) -> 0.0023750712 | I36: =IF(G36="","",G36/G$5) -> 0.00098439853 | J36: =IF(OR(D36="",G36=""),"",D36-G36) -> 1850595
B37: 세부 | C37: 차량유지비 | D37: 509000 | E37: =IF(OR(D37="",D25=0),"",D37/D25) -> 0.00017084421 | F37: =IF(D37="","",D37/D$5) -> 3.8717208e-05 | G37: 689502 | H37: =IF(OR(G37="",G25=0),"",G37/G25) -> 0.00029725272 | I37: =IF(G37="","",G37/G$5) -> 0.00012320268 | J37: =IF(OR(D37="",G37=""),"",D37-G37) -> -180502
B38: 세부 | C38: 운반비 | D38: 513850 | E38: =IF(OR(D38="",D25=0),"",D38/D25) -> 0.0001724721 | F38: =IF(D38="","",D38/D$5) -> 3.9086124e-05 | G38: 5006025 | H38: =IF(OR(G38="",G25=0),"",G38/G25) -> 0.0021581584 | I38: =IF(G38="","",G38/G$5) -> 0.00089449443 | J38: =IF(OR(D38="",G38=""),"",D38-G38) -> -4492175
B39: 세부 | C39: 교육훈련비 | D39: 1199818 | E39: =IF(OR(D39="",D25=0),"",D39/D25) -> 0.00040271504 | F39: =IF(D39="","",D39/D$5) -> 9.1264446e-05 | G39: 8262 | H39: =IF(OR(G39="",G25=0),"",G39/G25) -> 3.561849e-06 | I39: =IF(G39="","",G39/G$5) -> 1.4762837e-06 | J39: =IF(OR(D39="",G39=""),"",D39-G39) -> 1191556
B40: 세부 | C40: 도서인쇄비 | D40: 8368000 | E40: =IF(OR(D40="",D25=0),"",D40/D25) -> 0.0028086922 | F40: =IF(D40="","",D40/D$5) -> 0.00063651394 | G40: 8484800 | H40: =IF(OR(G40="",G25=0),"",G40/G25) -> 0.0036579008 | I40: =IF(G40="","",G40/G$5) -> 0.0015160944 | J40: =IF(OR(D40="",G40=""),"",D40-G40) -> -116800
B41: 세부 | C41: 소모품비 | D41: 9759123 | E41: =IF(OR(D41="",D25=0),"",D41/D25) -> 0.0032756182 | F41: =IF(D41="","",D41/D$5) -> 0.00074233005 | G41: 87634156 | H41: =IF(OR(G41="",G25=0),"",G41/G25) -> 0.037780153 | I41: =IF(G41="","",G41/G$5) -> 0.015658784 | J41: =IF(OR(D41="",G41=""),"",D41-G41) -> -77875033
...

Sheet 주석_보조자료
B1: 감사보고서 주석 · 보조 자료
B2: 주석 15 부가가치 관련자료는 천원 공시 — 보고서 표기 그대로. 운항원가의 "분해표"가 아니라 부가가치 6개 계정만 판관비/운항원가로 가른 표다.
B4: 1. 주석 15 부가가치 관련자료 (단위: 천원)
B5: 계정과목 | C5: 당기 판관비 | D5: 당기 운항원가 | E5: 당기 합계 | F5: 전기 판관비 | G5: 전기 운항원가 | H5: 전기 합계 | I5: 비고
B6: 급여 | C6: 1822879 | D6: 1253988 | E6: =C6+D6 -> 3076867 | F6: 925393 | G6: 598243 | H6: =F6+G6 -> 1523636
B7: 퇴직급여 | C7: 152420 | D7: 148252 | E7: =C7+D7 -> 300672 | F7: 47090 | G7: 21645 | H7: =F7+G7 -> 68735
B8: 복리후생비 | C8: 147553 | D8: 267351 | E8: =C8+D8 -> 414904 | F8: 149856 | G8: 122501 | H8: =F8+G8 -> 272357
B9: 인건비 소계 ← 선원비에 해당 | C9: =SUM(C6:C8) -> 2122852 | D9: =SUM(D6:D8) -> 1669591 | E9: =SUM(E6:E8) -> 3792443 | F9: =SUM(F6:F8) -> 1122339 | G9: =SUM(G6:G8) -> 742389 | H9: =SUM(H6:H8) -> 1864728
B10: 감가상각비 | C10: 0 | D10: 3349232 | E10: =C10+D10 -> 3349232 | F10: 0 | G10: 1665933 | H10: =F10+G10 -> 1665933
B11: 세금과공과 | C11: 62972 | D11: 48282 | E11: =C11+D11 -> 111254 | F11: 28336 | G11: 67295 | H11: =F11+G11 -> 95631
B12: 임차료 | C12: 74136 | D12: 30929 | E12: =C12+D12 -> 105065 | F12: 29850 | G12: 0 | H12: =F12+G12 -> 29850
B13: 주석 15 합계 | C13: =C9+SUM(C10:C12) -> 2259960 | D13: =D9+SUM(D10:D12) -> 5098034 | E13: =E9+SUM(E10:E12) -> 7357994 | F13: =F9+SUM(F10:F12) -> 1180525 | G13: =G9+SUM(G10:G12) -> 2475617 | H13: =H9+SUM(H10:H12) -> 3656142
B14: 운항원가 총액과의 간극 (천원) | D14: =ROUND(손익계산서_원본!$D$11/1000,0)-D13 -> 7148775 | I14: 손익계산서 운항원가(천원) − 주석 15 운항원가 열 = 보고서 어디에도 갈라 적혀 있지 않은 금액 (연료·항비·수선비·보험료 등)
B15: 주석 15를 운항원가 분해표로 읽으면 틀린다. 인건비 성격은 위 세 줄뿐이고, 선원/육상 운항지원 구분은 불가.
B17: 2. 그 밖의 주석 · 재무제표 값 (원)
B18: 항목 | C18: 당기 2024 | D18: 전기 2023 | I18: 출처
B19: 퇴직급여충당부채 당기 전입액 | C19: 300671000 | I19: 주석 7
B20: 영업활동으로 인한 현금흐름 | C20: -4645599309 | D20: -5004878618 | I20: 현금흐름표 — EBITDA 흑자의 현실 점검용
B21: 부가세예수금 (기말 잔액) | C21: 664296932 | D21: 212619820 | I21: 재무상태표 유동부채 (전기: 감사받지 아니함)

Sheet 원가구조_기준
B1: 원가 구조 — 기준 자료 (대저페리 제3기 · 참조 선박)
B2: 감사보고서 값에서 파생되는 중간값과 BEP 모형의 입력(고정비·준변동비·변동비)을 세운다. 단위: 원
B4: 1. 감사보고서 파생값
B5: 항목 | C5: 금액 | J5: 산식
B6: 여객수입 | C6: =손익계산서_원본!$D$6 -> 12813966995 | J6: 손익계산서 Ⅰ 여객수입
B7: 매출액 | C7: =손익계산서_원본!$D$5 -> 13146609166 | J7: 손익계산서 Ⅰ
B8: 여객 외 수입 (O) | C8: =원가구조_기준!$C$7-원가구조_기준!$C$6 -> 332642171 | J8: 매출액 − 여객수입 = 화물 + 임대료 등 · BEP 모형의 O
B9: 화물수입 | C9: =손익계산서_원본!$D$7 -> 323042171
B10: 화물 외 기타수입 (임대료 등) | C10: =원가구조_기준!$C$8-원가구조_기준!$C$9 -> 9600000
B11: 운항원가 (매출원가) | C11: =손익계산서_원본!$D$10 -> 12246808749
B12: 판매비와관리비 | C12: =손익계산서_원본!$D$25 -> 2979322526
B13: 영업이익(손실) | C13: =손익계산서_원본!$D$45 -> -2079522109
B14: 운항 감가상각비 | C14: =손익계산서_원본!$D$15 -> 3349232000 | J14: 전액 운항원가에 들어가 있다
B15: EBITDA | C15: =원가구조_기준!$C$13+원가구조_기준!$C$14 -> 1269709891 | J15: 영업이익 + 감가상각비
B16: 판관 급여영역 3과목 (직원급여·퇴직·복리) | C16: =손익계산서_원본!$D$26+손익계산서_원본!$D$27+손익계산서_원본!$D$28 -> 2122852250
B17: 판관 그 밖 (급여영역 제외) | C17: =원가구조_기준!$C$12-원가구조_기준!$C$16 -> 856470276
B18: 지급수수료 | C18: =손익계산서_원본!$D$42 -> 540820215
B19: 판관 그 밖 13과목 (지급수수료 제외) | C19: =원가구조_기준!$C$17-원가구조_기준!$C$18 -> 315650061
B20: 운항 인건비 3과목 (주석 15) | C20: =손익계산서_원본!$D$12+손익계산서_원본!$D$13+손익계산서_원본!$D$14 -> 1669591000 | J20: 해상직(선원+승무원) 인건비
B21: 전사 인건비 | C21: =원가구조_기준!$C$16+원가구조_기준!$C$20 -> 3792443250
B22: 운항 세금과공과 + 임차료 | C22: =손익계산서_원본!$D$16+손익계산서_원본!$D$17 -> 79211000
B23: 주석 15에 기재된 운항원가 | C23: =원가구조_기준!$C$20+원가구조_기준!$C$14+원가구조_기준!$C$22 -> 5098034000
B24: 운항기타 (주석 미기재 잔액) | C24: =원가구조_기준!$C$11-원가구조_기준!$C$23 -> 7148774749 | J24: 연료·항비·수선비 등 — 보고서에 갈라 적혀 있지 않다
B25: 2. 인력 · 1인당 인건비
B26: 항목 | C26: 값 | J26: 산식
B27: 판관 급여영역 1인당 (퇴직 포함) | C27: =원가구조_기준!$C$16/설정값!$D$90 -> 70761742 | J27: 급여영역 3과목 ÷ 기준 인원 30명
B28: 지상직 1인당 현금 인건비 (연) | C28: =(손익계산서_원본!$D$26+손익계산서_원본!$D$28)/설정값!$D$90 -> 65681069 | J28: (직원급여 + 복리후생비) ÷ 30 — 헤더 "1인당 인건비"
B29: 지상직 1인당 퇴직급여 (비현금) | C29: =손익계산서_원본!$D$27/설정값!$D$90 -> 5080673.1
B30: 지상직 1인당 현금 인건비 (월) | C30: =원가구조_기준!$C$28/12 -> 5473422.4
B31: 해상직 인원 (선원 + 승무원) | C31: =MAX(1,설정값!$D$9+설정값!$D$10) -> 20
B32: 해상직 1인당 인건비 (퇴직 포함) | C32: =원가구조_기준!$C$20/원가구조_기준!$C$31 -> 83479550
B33: 해상직 1인당 ÷ 지상직 1인당(현금) | C33: =원가구조_기준!$C$32/원가구조_기준!$C$28 -> 1.2709834
B34: 판관 급여영역 (설정 지상직 인원 기준) | C34: =설정값!$D$8*원가구조_기준!$C$27 -> 2.1228523e+09 | J34: 지상직 × 1인당 — 판관 급여영역만 직원 수에 따라 움직인다
B35: 3. 좌석 등급 · 실현 단가 · 승객수
B36: 등급 | C36: 운임 | D36: 배율 | E36: 구성비 | J36: 비고
B37: 이코노미 | C37: =설정값!$D$12*운임_화물_선박!$C$12 -> 81000 | D37: =운임_화물_선박!$C$12 -> 1 | E37: =MAX(0,설정값!$D$14) -> 1
B38: 비즈니스 | C38: =설정값!$D$12*운임_화물_선박!$E$12 -> 121500 | D38: =운임_화물_선박!$E$12 -> 1.5 | E38: =MAX(0,설정값!$D$15) -> 0
B39: 퍼스트 | C39: =설정값!$D$12*운임_화물_선박!$G$12 -> 171500 | D39: =운임_화물_선박!$G$12 -> 2.117284 | E39: =MAX(0,설정값!$D$16) -> 0
B40: 구성비 합계 | C40: =SUM(E37:E39) -> 1
B41: 배율 × 구성비 합 | C41: =SUMPRODUCT(D37:D39,E37:E39) -> 1
...

Sheet 대조선박_손익
B1: 손익계산서 — 대조 선박 (하카타 항로 투입 시나리오 · 단일연도)
B2: 감사보고서 원가 구조 위에 대조 선박의 인력·항차·운임·선가·차입 조건을 얹어 다시 세운 손익. 단위: 원
B4: 1. 대조 선박 파생값 (스케일 규칙)
B5: 항목 | C5: 값 | J5: 산식 · 규칙
B6: 대조 선박 | C6: =설정값!$D$39 -> 산타모니카호
B7: 여객정원 | C7: =IFERROR(INDEX(운임_화물_선박!$G$18:$G$21,MATCH(대조선박_손익!$C$6,운임_화물_선박!$B$18:$B$21,0)),0) -> 606 | J7: 운임_화물_선박 시트 선박 제원
B8: 분석 상태 | C8: =IFERROR(IF(LEFT(INDEX(운임_화물_선박!$K$18:$K$21,MATCH(대조선박_손익!$C$6,운임_화물_선박!$B$18:$B$21,0)),2)="보류","보류중 — 원가 자료 미확보, 결과를 확정으로 읽지 말 것","분석 가능"),"") -> 분석 가능
B9: 임대료수입 제외 (산타모니카호) | C9: =IF(대조선박_손익!$C$6="산타모니카호","O","X") -> O | J9: 산타모니카호는 우리 임대료수입 계정 대상이 아님
B10: 대조 해상직 인원 (선원+승무원) | C10: =MAX(1,설정값!$D$41+설정값!$D$42) -> 20
B11: 해상직 비율 (hR) | C11: =대조선박_손익!$C$10/원가구조_기준!$C$31 -> 1 | J11: 대조 해상직 ÷ 참조 해상직 → 운항 인건비 3과목에 곱함
B12: 지상직 비율 (sR) | C12: =설정값!$D$40/설정값!$D$90 -> 1 | J12: 대조 지상직 ÷ 30명 → 판관 급여 3과목에 곱함
B13: 항차 비율 | C13: =설정값!$D$43/설정값!$D$11 -> 1.2048193 | J13: 대조 항차 ÷ 참조 항차 → 운항기타 세목에 곱함
B14: 연료 원화 단가 — 기준 (원/MT) | C14: =설정값!$D$45*설정값!$D$47 -> 1115200
B15: 연료 원화 단가 — 현재 (원/MT) | C15: =설정값!$D$46*설정값!$D$48 -> 1783768
B16: 연료비 증가 배율 | C16: =IF(설정값!$D$49="O",대조선박_손익!$C$15/대조선박_손익!$C$14,1) -> 1.599505 | J16: (현재 $/MT × 환율) ÷ (기준 $/MT × 환율) — 연료비 세목에만
B17: 좌석 — 이코노미 (운임 · 배율 · 구성비) | C17: =설정값!$D$61*운임_화물_선박!$C$12 -> 90000 | D17: =운임_화물_선박!$C$12 -> 1 | E17: =MAX(0,설정값!$D$63) -> 1
B18: 좌석 — 비즈니스 (운임 · 배율 · 구성비) | C18: =설정값!$D$61*운임_화물_선박!$E$12 -> 135000 | D18: =운임_화물_선박!$E$12 -> 1.5 | E18: =MAX(0,설정값!$D$64) -> 0
B19: 좌석 — 퍼스트 (운임 · 배율 · 구성비) | C19: =설정값!$D$61*운임_화물_선박!$G$12 -> 190555.56 | D19: =운임_화물_선박!$G$12 -> 2.117284 | E19: =MAX(0,설정값!$D$65) -> 0
B20: 구성비 합계 | C20: =SUM(E17:E19) -> 1
B21: 배율 × 구성비 합 | C21: =SUMPRODUCT(D17:D19,E17:E19) -> 1
B22: 가중평균 운임 | C22: =IF(대조선박_손익!$C$21>0,설정값!$D$61*대조선박_손익!$C$21/대조선박_손익!$C$20,설정값!$D$61) -> 90000
B23: 실현 단가 (가중평균 + 유류할증료) | C23: =대조선박_손익!$C$22+설정값!$D$62 -> 120000
B24: 항차당 인원 (정원 × 승선율) | C24: =IF(OR(설정값!$D$59="O",대조선박_손익!$C$7=0),IF(설정값!$D$43>0,N(설정값!$D$60)/설정값!$D$43,0),ROUND(대조선박_손익!$C$7*설정값!$D$58,2)) -> 303
B25: 연간 승객수 | C25: =IF(OR(설정값!$D$59="O",대조선박_손익!$C$7=0),ROUND(N(설정값!$D$60),0),ROUND(대조선박_손익!$C$24*설정값!$D$43,0)) -> 181800 | J25: 승선율 → 항차당 인원 → 연간 승객수 (직접 입력이면 입력값)
B26: 승선율 (결과) | C26: =IF(대조선박_손익!$C$7>0,대조선박_손익!$C$25/(대조선박_손익!$C$7*설정값!$D$43),0) -> 0.5
B27: 가동율 (편도 항차) | C27: =설정값!$D$43/설정값!$D$91 -> 0.82191781
B28: 적재 케이스 항차당 최대 차량 수입 | C28: =IFERROR(INDEX(운임_화물_선박!$L$55:$L$59,MATCH(설정값!$D$67,운임_화물_선박!$B$55:$B$59,0)),0) -> 6579320 | J28: 운임_화물_선박 4번 표
B29: 선적율 적용 항차당 수입 | C29: =대조선박_손익!$C$28*설정값!$D$66 -> 1973796
B30: 연간 화물수입 | C30: =대조선박_손익!$C$28*설정값!$D$66*설정값!$D$43 -> 1184277600 | J30: 케이스 수입 × 선적율 × 대조 항차 (+α: 운임 미산정 항목)
B31: 임대료수입 | C31: =IF(대조선박_손익!$C$9="O",0,원가구조_기준!$C$10) -> 0
B32: 여객 외 수입 (O) | C32: =대조선박_손익!$C$30+대조선박_손익!$C$31 -> 1184277600
B33: 감가상각비 | C33: =IF(N(설정값!$D$50)>0,N(설정값!$D$50)*1000000*(1-설정값!$D$52)/MAX(1,설정값!$D$51),원가구조_기준!$C$14) -> 0 | J33: 선가 × (1 − 잔존가치) ÷ 내용연수 (정액법) · 선가가 비면 감사보고서 감가상각비
B34: 운항 인건비 3과목 | C34: =원가구조_기준!$C$20*대조선박_손익!$C$11 -> 1669591000
B35: 판관 급여영역 | C35: =설정값!$D$40*원가구조_기준!$C$27 -> 2.1228523e+09
B36: 지급수수료 배율 | C36: =IF(설정값!$E$36="변동",IF(원가구조_기준!$C$45>0,대조선박_손익!$C$25/원가구조_기준!$C$45,1),IF(설정값!$E$36="준변동",설정값!$D$43/설정값!$D$11,1)) -> 1.2619909 | J36: 원가 구성표의 지급수수료 성격을 따른다 (변동: 대조 승객 ÷ 실적 역산 승객)
B37: 2. 운항기타 세목 산출 ( "운항기타 — 산출 근거")
B38: 세목 | C38: 기준금액 (감사보고서 비례) | D38: 비율(정규화) | E38: 항차비율 | F38: 연료할증 | G38: 적용금액
B39: 연료비 | C39: =원가구조_기준!$C$53 -> 5.9656525e+09 | D39: =IFERROR(C39/원가구조_기준!$C$24,0) -> 0.8345 | E39: =대조선박_손익!$C$13 -> 1.2048193 | F39: =대조선박_손익!$C$16 -> 1.599505 | G39: =C39*E39*F39 -> 1.1496495e+10
B40: 항비 | C40: =원가구조_기준!$C$54 -> 7.9708838e+08 | D40: =IFERROR(C40/원가구조_기준!$C$24,0) -> 0.1115 | E40: =대조선박_손익!$C$13 -> 1.2048193 | F40: 1 | G40: =C40*E40*F40 -> 9.6034745e+08
B41: 보험료 | C41: =원가구조_기준!$C$55 -> 3.6673214e+08 | D41: =IFERROR(C41/원가구조_기준!$C$24,0) -> 0.0513 | E41: =대조선박_손익!$C$13 -> 1.2048193 | F41: 1 | G41: =C41*E41*F41 -> 4.4184596e+08
...

Sheet 차입금_상환
B1: 차입금 상환 스케줄 — 대조 선박
B2: 이자비용은 손익계산서 항목, 원금 상환은 현금유출. 10개년 예상의 "선체이자"는 이 표의 연도별 이자를 그대로 쓴다. 단위: 원
B4: 1. 차입 조건 · 첫해 원리금 ( debtService)
B5: 항목 | C5: 값 | I5: 산식
B6: 차입금 (원) | C6: =MAX(0,N(설정값!$D$53))*1000000 -> 20000000000 | I6: 설정값(백만원) × 1,000,000
B7: 이자율 | C7: =IF(설정값!$D$104="O",0.0156,N(설정값!$D$54)) -> 0.035 | I7: 설정값 D54. 단, E 섹션 "엔화대출 1.56% 적용"이 O 면 1.56% 로 고정
B8: 상환기간 (년) | C8: =MAX(1,N(설정값!$D$55)) -> 15
B9: 거치기간 (년) | C9: =MAX(0,N(설정값!$D$56)) -> 3
B10: 상환방식 | C10: =설정값!$D$57 -> 원금균등
B11: 원금 상환 햇수 | C11: =MAX(1,차입금_상환!$C$8-차입금_상환!$C$9) -> 12 | I11: 상환기간 − 거치기간
B12: 원리금균등 연 상환액 (PMT) | C12: =IF(차입금_상환!$C$7=0,차입금_상환!$C$6/차입금_상환!$C$11,차입금_상환!$C$6*차입금_상환!$C$7/(1-(1+차입금_상환!$C$7)^(-차입금_상환!$C$11))) -> 2.069679e+09 | I12: P·r / (1 − (1+r)^−n)
B13: 첫해 이자 | C13: =차입금_상환!$C$6*차입금_상환!$C$7 -> 7e+08 | I13: 손익계산서(단일연도) 영업외비용 이자비용
B14: 첫해 원금상환 | C14: =IF(차입금_상환!$C$6<=0,0,IF(차입금_상환!$C$10="원리금균등",차입금_상환!$C$12-차입금_상환!$C$13,IF(차입금_상환!$C$10="원금균등",차입금_상환!$C$6/차입금_상환!$C$11,0))) -> 1.6666667e+09 | I14: 규칙: 원리금균등은 PMT − 이자 (거치 중에도 동일 적용) · 원금균등 P/n · 만기일시 0
B15: 첫해 원리금 | C15: =차입금_상환!$C$13+차입금_상환!$C$14 -> 2.3666667e+09
B16: 총 상환액 | C16: =IF(차입금_상환!$C$6<=0,0,IF(차입금_상환!$C$10="원리금균등",차입금_상환!$C$12*차입금_상환!$C$11,IF(차입금_상환!$C$10="원금균등",차입금_상환!$C$6+차입금_상환!$C$7*차입금_상환!$C$6*(차입금_상환!$C$11+1)/2,차입금_상환!$C$13*차입금_상환!$C$8+차입금_상환!$C$6))) -> 24550000000
B17: 총 이자 | C17: =차입금_상환!$C$16-차입금_상환!$C$6 -> 4550000000
B18: 2. 연도별 상환 스케줄 ( interestSeries)
B19: 연차 | C19: 10개년 표 열 | D19: 기초 잔액 | E19: 이자 | F19: 원금 상환 | G19: 원리금 | H19: 기말 잔액 | I19: 비고
B20: 1 | C20: y+0 | D20: =차입금_상환!$C$6 -> 20000000000 | E20: =IF(OR(D20<=0.000001,차입금_상환!$C$7<=0),0,D20*차입금_상환!$C$7) -> 7e+08 | F20: =IF(D20<=0.000001,0,IF(B20<=차입금_상환!$C$9,0,IF(차입금_상환!$C$10="원리금균등",MIN(D20,MAX(0,차입금_상환!$C$12-E20)),IF(차입금_상환!$C$10="원금균등",MIN(D20,차입금_상환!$C$6/차입금_상환!$C$11),IF(B20=차입금_상환!$C$8,D20,0))))) -> 0 | G20: =E20+F20 -> 7e+08 | H20: =MAX(0,D20-F20) -> 20000000000
B21: 2 | C21: y+1 | D21: =H20 -> 20000000000 | E21: =IF(OR(D21<=0.000001,차입금_상환!$C$7<=0),0,D21*차입금_상환!$C$7) -> 7e+08 | F21: =IF(D21<=0.000001,0,IF(B21<=차입금_상환!$C$9,0,IF(차입금_상환!$C$10="원리금균등",MIN(D21,MAX(0,차입금_상환!$C$12-E21)),IF(차입금_상환!$C$10="원금균등",MIN(D21,차입금_상환!$C$6/차입금_상환!$C$11),IF(B21=차입금_상환!$C$8,D21,0))))) -> 0 | G21: =E21+F21 -> 7e+08 | H21: =MAX(0,D21-F21) -> 20000000000
B22: 3 | C22: y+2 | D22: =H21 -> 20000000000 | E22: =IF(OR(D22<=0.000001,차입금_상환!$C$7<=0),0,D22*차입금_상환!$C$7) -> 7e+08 | F22: =IF(D22<=0.000001,0,IF(B22<=차입금_상환!$C$9,0,IF(차입금_상환!$C$10="원리금균등",MIN(D22,MAX(0,차입금_상환!$C$12-E22)),IF(차입금_상환!$C$10="원금균등",MIN(D22,차입금_상환!$C$6/차입금_상환!$C$11),IF(B22=차입금_상환!$C$8,D22,0))))) -> 0 | G22: =E22+F22 -> 7e+08 | H22: =MAX(0,D22-F22) -> 20000000000
B23: 4 | C23: y+3 | D23: =H22 -> 20000000000 | E23: =IF(OR(D23<=0.000001,차입금_상환!$C$7<=0),0,D23*차입금_상환!$C$7) -> 7e+08 | F23: =IF(D23<=0.000001,0,IF(B23<=차입금_상환!$C$9,0,IF(차입금_상환!$C$10="원리금균등",MIN(D23,MAX(0,차입금_상환!$C$12-E23)),IF(차입금_상환!$C$10="원금균등",MIN(D23,차입금_상환!$C$6/차입금_상환!$C$11),IF(B23=차입금_상환!$C$8,D23,0))))) -> 1.6666667e+09 | G23: =E23+F23 -> 2.3666667e+09 | H23: =MAX(0,D23-F23) -> 1.8333333e+10
B24: 5 | C24: y+4 | D24: =H23 -> 1.8333333e+10 | E24: =IF(OR(D24<=0.000001,차입금_상환!$C$7<=0),0,D24*차입금_상환!$C$7) -> 6.4166667e+08 | F24: =IF(D24<=0.000001,0,IF(B24<=차입금_상환!$C$9,0,IF(차입금_상환!$C$10="원리금균등",MIN(D24,MAX(0,차입금_상환!$C$12-E24)),IF(차입금_상환!$C$10="원금균등",MIN(D24,차입금_상환!$C$6/차입금_상환!$C$11),IF(B24=차입금_상환!$C$8,D24,0))))) -> 1.6666667e+09 | G24: =E24+F24 -> 2.3083333e+09 | H24: =MAX(0,D24-F24) -> 1.6666667e+10
B25: 6 | C25: y+5 | D25: =H24 -> 1.6666667e+10 | E25: =IF(OR(D25<=0.000001,차입금_상환!$C$7<=0),0,D25*차입금_상환!$C$7) -> 5.8333333e+08 | F25: =IF(D25<=0.000001,0,IF(B25<=차입금_상환!$C$9,0,IF(차입금_상환!$C$10="원리금균등",MIN(D25,MAX(0,차입금_상환!$C$12-E25)),IF(차입금_상환!$C$10="원금균등",MIN(D25,차입금_상환!$C$6/차입금_상환!$C$11),IF(B25=차입금_상환!$C$8,D25,0))))) -> 1.6666667e+09 | G25: =E25+F25 -> 2250000000 | H25: =MAX(0,D25-F25) -> 15000000000
B26: 7 | C26: y+6 | D26: =H25 -> 15000000000 | E26: =IF(OR(D26<=0.000001,차입금_상환!$C$7<=0),0,D26*차입금_상환!$C$7) -> 5.25e+08 | F26: =IF(D26<=0.000001,0,IF(B26<=차입금_상환!$C$9,0,IF(차입금_상환!$C$10="원리금균등",MIN(D26,MAX(0,차입금_상환!$C$12-E26)),IF(차입금_상환!$C$10="원금균등",MIN(D26,차입금_상환!$C$6/차입금_상환!$C$11),IF(B26=차입금_상환!$C$8,D26,0))))) -> 1.6666667e+09 | G26: =E26+F26 -> 2.1916667e+09 | H26: =MAX(0,D26-F26) -> 1.3333333e+10
B27: 8 | C27: y+7 | D27: =H26 -> 1.3333333e+10 | E27: =IF(OR(D27<=0.000001,차입금_상환!$C$7<=0),0,D27*차입금_상환!$C$7) -> 4.6666667e+08 | F27: =IF(D27<=0.000001,0,IF(B27<=차입금_상환!$C$9,0,IF(차입금_상환!$C$10="원리금균등",MIN(D27,MAX(0,차입금_상환!$C$12-E27)),IF(차입금_상환!$C$10="원금균등",MIN(D27,차입금_상환!$C$6/차입금_상환!$C$11),IF(B27=차입금_상환!$C$8,D27,0))))) -> 1.6666667e+09 | G27: =E27+F27 -> 2.1333333e+09 | H27: =MAX(0,D27-F27) -> 1.1666667e+10
B28: 9 | C28: y+8 | D28: =H27 -> 1.1666667e+10 | E28: =IF(OR(D28<=0.000001,차입금_상환!$C$7<=0),0,D28*차입금_상환!$C$7) -> 4.0833333e+08 | F28: =IF(D28<=0.000001,0,IF(B28<=차입금_상환!$C$9,0,IF(차입금_상환!$C$10="원리금균등",MIN(D28,MAX(0,차입금_상환!$C$12-E28)),IF(차입금_상환!$C$10="원금균등",MIN(D28,차입금_상환!$C$6/차입금_상환!$C$11),IF(B28=차입금_상환!$C$8,D28,0))))) -> 1.6666667e+09 | G28: =E28+F28 -> 2.075e+09 | H28: =MAX(0,D28-F28) -> 1e+10
B29: 10 | C29: y+9 | D29: =H28 -> 1e+10 | E29: =IF(OR(D29<=0.000001,차입금_상환!$C$7<=0),0,D29*차입금_상환!$C$7) -> 3.5e+08 | F29: =IF(D29<=0.000001,0,IF(B29<=차입금_상환!$C$9,0,IF(차입금_상환!$C$10="원리금균등",MIN(D29,MAX(0,차입금_상환!$C$12-E29)),IF(차입금_상환!$C$10="원금균등",MIN(D29,차입금_상환!$C$6/차입금_상환!$C$11),IF(B29=차입금_상환!$C$8,D29,0))))) -> 1.6666667e+09 | G29: =E29+F29 -> 2.0166667e+09 | H29: =MAX(0,D29-F29) -> 8.3333333e+09
B30: 11 | C30: y+10 | D30: =H29 -> 8.3333333e+09 | E30: =IF(OR(D30<=0.000001,차입금_상환!$C$7<=0),0,D30*차입금_상환!$C$7) -> 2.9166667e+08 | F30: =IF(D30<=0.000001,0,IF(B30<=차입금_상환!$C$9,0,IF(차입금_상환!$C$10="원리금균등",MIN(D30,MAX(0,차입금_상환!$C$12-E30)),IF(차입금_상환!$C$10="원금균등",MIN(D30,차입금_상환!$C$6/차입금_상환!$C$11),IF(B30=차입금_상환!$C$8,D30,0))))) -> 1.6666667e+09 | G30: =E30+F30 -> 1.9583333e+09 | H30: =MAX(0,D30-F30) -> 6.6666667e+09
B31: 12 | D31: =H30 -> 6.6666667e+09 | E31: =IF(OR(D31<=0.000001,차입금_상환!$C$7<=0),0,D31*차입금_상환!$C$7) -> 2.3333333e+08 | F31: =IF(D31<=0.000001,0,IF(B31<=차입금_상환!$C$9,0,IF(차입금_상환!$C$10="원리금균등",MIN(D31,MAX(0,차입금_상환!$C$12-E31)),IF(차입금_상환!$C$10="원금균등",MIN(D31,차입금_상환!$C$6/차입금_상환!$C$11),IF(B31=차입금_상환!$C$8,D31,0))))) -> 1.6666667e+09 | G31: =E31+F31 -> 1.9e+09 | H31: =MAX(0,D31-F31) -> 5e+09
B32: 13 | D32: =H31 -> 5e+09 | E32: =IF(OR(D32<=0.000001,차입금_상환!$C$7<=0),0,D32*차입금_상환!$C$7) -> 1.75e+08 | F32: =IF(D32<=0.000001,0,IF(B32<=차입금_상환!$C$9,0,IF(차입금_상환!$C$10="원리금균등",MIN(D32,MAX(0,차입금_상환!$C$12-E32)),IF(차입금_상환!$C$10="원금균등",MIN(D32,차입금_상환!$C$6/차입금_상환!$C$11),IF(B32=차입금_상환!$C$8,D32,0))))) -> 1.6666667e+09 | G32: =E32+F32 -> 1.8416667e+09 | H32: =MAX(0,D32-F32) -> 3.3333333e+09
B33: 14 | D33: =H32 -> 3.3333333e+09 | E33: =IF(OR(D33<=0.000001,차입금_상환!$C$7<=0),0,D33*차입금_상환!$C$7) -> 1.1666667e+08 | F33: =IF(D33<=0.000001,0,IF(B33<=차입금_상환!$C$9,0,IF(차입금_상환!$C$10="원리금균등",MIN(D33,MAX(0,차입금_상환!$C$12-E33)),IF(차입금_상환!$C$10="원금균등",MIN(D33,차입금_상환!$C$6/차입금_상환!$C$11),IF(B33=차입금_상환!$C$8,D33,0))))) -> 1.6666667e+09 | G33: =E33+F33 -> 1.7833333e+09 | H33: =MAX(0,D33-F33) -> 1.6666667e+09
B34: 15 | D34: =H33 -> 1.6666667e+09 | E34: =IF(OR(D34<=0.000001,차입금_상환!$C$7<=0),0,D34*차입금_상환!$C$7) -> 58333333 | F34: =IF(D34<=0.000001,0,IF(B34<=차입금_상환!$C$9,0,IF(차입금_상환!$C$10="원리금균등",MIN(D34,MAX(0,차입금_상환!$C$12-E34)),IF(차입금_상환!$C$10="원금균등",MIN(D34,차입금_상환!$C$6/차입금_상환!$C$11),IF(B34=차입금_상환!$C$8,D34,0))))) -> 1.6666667e+09 | G34: =E34+F34 -> 1725000000 | H34: =MAX(0,D34-F34) -> 4.7683716e-07
B35: 합계 | E35: =SUM(E20:E34) -> 6.65e+09 | F35: =SUM(F20:F34) -> 20000000000 | G35: =SUM(G20:G34) -> 26650000000
B36: 거치기간에는 이자만, 이후 남은 해에 걸쳐 원금 상환. 만기일시는 만기 연도에 잔액 일시 상환. 이자율 0이면 이자 0.

Sheet 10개년_예상
B1: 10개년 예상 손익계산서 — 대조 선박 (단위: 백만원)
B4: 과 목 | C4: 성장률 | D4: 58기 | E4: 59기 | F4: 60기 | G4: 61기 | H4: 62기 | I4: 63기 | J4: 64기 | K4: 65기 | L4: 66기 | M4: 67기 | N4: 68기 | O4: y+1~y+10 평균 | P4: 근거
B5: n (경과 연수) | D5: 0 | E5: 1 | F5: 2 | G5: 3 | H5: 4 | I5: 5 | J5: 6 | K5: 7 | L5: 8 | M5: 9 | N5: 10
B6: 회계연도 | D6: 2025 | E6: 2026 | F6: 2027 | G6: 2028 | H6: 2029 | I6: 2030 | J6: 2031 | K6: 2032 | L6: 2033 | M6: 2034 | N6: 2035
B7: Ⅰ. 매출액 | D7: =D8++D9++D10++D11 -> 23000.278 | E7: =E8++E9++E10++E11 -> 23610.627 | F7: =F8++F9++F10++F11 -> 24237.263 | G7: =G8++G9++G10++G11 -> 24880.624 | H7: =H8++H9++H10++H11 -> 25541.156 | I7: =I8++I9++I10++I11 -> 26219.32 | J7: =J8++J9++J10++J11 -> 26915.589 | K7: =K8++K9++K10++K11 -> 27630.447 | ... N7: =N8++N9++N10++N11 -> 29891.608 | O7: =AVERAGE(E7:N7) -> 26640.896
B8: 여객수입 | C8: =설정값!$D$70 -> 0.027 | D8: =대조선박_손익!$C$49/1000000 -> 21816 | E8: =$D8*(1+$C8)^E$5 -> 22405.032 | F8: =$D8*(1+$C8)^F$5 -> 23009.968 | G8: =$D8*(1+$C8)^G$5 -> 23631.237 | H8: =$D8*(1+$C8)^H$5 -> 24269.28 | I8: =$D8*(1+$C8)^I$5 -> 24924.551 | J8: =$D8*(1+$C8)^J$5 -> 25597.514 | K8: =$D8*(1+$C8)^K$5 -> 26288.647 | L8: =$D8*(1+$C8)^L$5 -> 26998.44 | ... N8: =$D8*(1+$C8)^N$5 -> 28476.038 | O8: =AVERAGE(E8:N8) -> 25332.81
B9: 화물수입 (+α) | C9: =설정값!$D$71 -> 0.018 | D9: =대조선박_손익!$C$50/1000000 -> 1184.2776 | E9: =$D9*(1+$C9)^E$5 -> 1205.5946 | F9: =$D9*(1+$C9)^F$5 -> 1227.2953 | G9: =$D9*(1+$C9)^G$5 -> 1249.3866 | H9: =$D9*(1+$C9)^H$5 -> 1271.8756 | I9: =$D9*(1+$C9)^I$5 -> 1294.7693 | J9: =$D9*(1+$C9)^J$5 -> 1318.0752 | K9: =$D9*(1+$C9)^K$5 -> 1341.8005 | L9: =$D9*(1+$C9)^L$5 -> 1365.9529 | ... N9: =$D9*(1+$C9)^N$5 -> 1415.5698 | O9: =AVERAGE(E9:N9) -> 1308.086 | P9: +α: 운임 미산정 항목(캐러밴·일반화물)의 이익 여분
B10: 임대료수입 | C10: =설정값!$D$72 -> 0 | D10: =대조선박_손익!$C$51/1000000 -> 0 | E10: =$D10*(1+$C10)^E$5 -> 0 | F10: =$D10*(1+$C10)^F$5 -> 0 | G10: =$D10*(1+$C10)^G$5 -> 0 | H10: =$D10*(1+$C10)^H$5 -> 0 | I10: =$D10*(1+$C10)^I$5 -> 0 | J10: =$D10*(1+$C10)^J$5 -> 0 | K10: =$D10*(1+$C10)^K$5 -> 0 | L10: =$D10*(1+$C10)^L$5 -> 0 | ... N10: =$D10*(1+$C10)^N$5 -> 0 | O10: =AVERAGE(E10:N10) -> 0
B11: 면세수입 (감안) | D11: 0 | E11: 0 | F11: 0 | G11: 0 | H11: 0 | I11: 0 | J11: 0 | K11: 0 | L11: 0 | M11: 0 | N11: 0 | O11: =AVERAGE(E11:N11) -> 0 | P11: 대저페리는 내항선이라 현재 없음 — 외항선이면 면세품 판매 수입 기대. 잠재 매출로 감안 (미반영)
B12: Ⅱ. 운항원가 (−) | D12: =D13++D14++D15++D16++D17++D18++D19++D25 -> 16070.746 | E12: =E13++E14++E15++E16++E17++E18++E19++E25 -> 16145.008 | F12: =F13++F14++F15++F16++F17++F18++F19++F25 -> 16230.242 | G12: =G13++G14++G15++G16++G17++G18++G19++G25 -> 16327.127 | H12: =H13++H14++H15++H16++H17++H18++H19++H25 -> 16378.064 | I12: =I13++I14++I15++I16++I17++I18++I19++I25 -> 16442.182 | J12: =J13++J14++J15++J16++J17++J18++J19++J25 -> 16520.337 | K12: =K13++K14++K15++K16++K17++K18++K19++K25 -> 16613.46 | ... N12: =N13++N14++N15++N16++N17++N18++N19++N25 -> 16993.133 | O12: =AVERAGE(E12:N12) -> 16522.083
B13: 급여 (해상직원) | C13: =설정값!$D$73 -> 0.0271 | D13: =대조선박_손익!$C$53/1000000 -> 1253.988 | E13: =$D13*(1+$C13)^E$5 -> 1287.9711 | F13: =$D13*(1+$C13)^F$5 -> 1322.8751 | G13: =$D13*(1+$C13)^G$5 -> 1358.725 | H13: =$D13*(1+$C13)^H$5 -> 1395.5465 | I13: =$D13*(1+$C13)^I$5 -> 1433.3658 | J13: =$D13*(1+$C13)^J$5 -> 1472.21 | K13: =$D13*(1+$C13)^K$5 -> 1512.1069 | L13: =$D13*(1+$C13)^L$5 -> 1553.085 | ... N13: =$D13*(1+$C13)^N$5 -> 1638.4028 | O13: =AVERAGE(E13:N13) -> 1456.9462
B14: 퇴직급여 (해상직원) | C14: =설정값!$D$74 -> 0.0271 | D14: =대조선박_손익!$C$54/1000000 -> 148.252 | E14: =$D14*(1+$C14)^E$5 -> 152.26963 | F14: =$D14*(1+$C14)^F$5 -> 156.39614 | G14: =$D14*(1+$C14)^G$5 -> 160.63447 | H14: =$D14*(1+$C14)^H$5 -> 164.98767 | I14: =$D14*(1+$C14)^I$5 -> 169.45883 | J14: =$D14*(1+$C14)^J$5 -> 174.05117 | K14: =$D14*(1+$C14)^K$5 -> 178.76795 | L14: =$D14*(1+$C14)^L$5 -> 183.61256 | ... N14: =$D14*(1+$C14)^N$5 -> 193.69921 | O14: =AVERAGE(E14:N14) -> 172.24661
B15: 복리후생비 (해상직원) | C15: =설정값!$D$75 -> 0.024 | D15: =대조선박_손익!$C$55/1000000 -> 267.351 | E15: =$D15*(1+$C15)^E$5 -> 273.76742 | F15: =$D15*(1+$C15)^F$5 -> 280.33784 | G15: =$D15*(1+$C15)^G$5 -> 287.06595 | H15: =$D15*(1+$C15)^H$5 -> 293.95553 | I15: =$D15*(1+$C15)^I$5 -> 301.01047 | J15: =$D15*(1+$C15)^J$5 -> 308.23472 | K15: =$D15*(1+$C15)^K$5 -> 315.63235 | L15: =$D15*(1+$C15)^L$5 -> 323.20753 | ... N15: =$D15*(1+$C15)^N$5 -> 338.90766 | O15: =AVERAGE(E15:N15) -> 305.3084
B16: 감가상각비 | C16: =설정값!$D$76 -> 0 | D16: =대조선박_손익!$C$56/1000000 -> 0 | E16: =$D16*(1+$C16)^E$5 -> 0 | F16: =$D16*(1+$C16)^F$5 -> 0 | G16: =$D16*(1+$C16)^G$5 -> 0 | H16: =$D16*(1+$C16)^H$5 -> 0 | I16: =$D16*(1+$C16)^I$5 -> 0 | J16: =$D16*(1+$C16)^J$5 -> 0 | K16: =$D16*(1+$C16)^K$5 -> 0 | L16: =$D16*(1+$C16)^L$5 -> 0 | ... N16: =$D16*(1+$C16)^N$5 -> 0 | O16: =AVERAGE(E16:N16) -> 0
B17: 세금과공과 | C17: =설정값!$D$77 -> 0.0292 | D17: =대조선박_손익!$C$57/1000000 -> 48.282 | E17: =$D17*(1+$C17)^E$5 -> 49.691834 | F17: =$D17*(1+$C17)^F$5 -> 51.142836 | G17: =$D17*(1+$C17)^G$5 -> 52.636207 | H17: =$D17*(1+$C17)^H$5 -> 54.173184 | I17: =$D17*(1+$C17)^I$5 -> 55.755041 | J17: =$D17*(1+$C17)^J$5 -> 57.383088 | K17: =$D17*(1+$C17)^K$5 -> 59.058674 | L17: =$D17*(1+$C17)^L$5 -> 60.783188 | ... N17: =$D17*(1+$C17)^N$5 -> 64.384752 | O17: =AVERAGE(E17:N17) -> 56.756686
B18: 임차료 | C18: =설정값!$D$78 -> 0 | D18: =대조선박_손익!$C$58/1000000 -> 30.929 | E18: =$D18*(1+$C18)^E$5 -> 30.929 | F18: =$D18*(1+$C18)^F$5 -> 30.929 | G18: =$D18*(1+$C18)^G$5 -> 30.929 | H18: =$D18*(1+$C18)^H$5 -> 30.929 | I18: =$D18*(1+$C18)^I$5 -> 30.929 | J18: =$D18*(1+$C18)^J$5 -> 30.929 | K18: =$D18*(1+$C18)^K$5 -> 30.929 | L18: =$D18*(1+$C18)^L$5 -> 30.929 | ... N18: =$D18*(1+$C18)^N$5 -> 30.929 | O18: =AVERAGE(E18:N18) -> 30.929
B19: 운항기타 | D19: =D20++D21++D22++D23++D24 -> 13621.944 | E19: =E20++E21++E22++E23++E24 -> 13650.379 | F19: =F20++F21++F22++F23++F24 -> 13688.561 | G19: =G20++G21++G22++G23++G24 -> 13737.136 | H19: =H20++H21++H22++H23++H24 -> 13796.806 | I19: =I20++I21++I22++I23++I24 -> 13868.329 | J19: =J20++J21++J22++J23++J24 -> 13952.529 | K19: =K20++K21++K22++K23++K24 -> 14050.298 | ... N19: =N20++N21++N22++N23++N24 -> 14435.143 | O19: =AVERAGE(E19:N19) -> 13963.229 | P19: 아래 5개 세목의 합
B20: · 연료비 | C20: =설정값!$D$79 -> -0.0089 | D20: =대조선박_손익!$C$60/1000000 -> 11496.495 | E20: =$D20*(1+$C20)^E$5 -> 11394.177 | F20: =$D20*(1+$C20)^F$5 -> 11292.768 | G20: =$D20*(1+$C20)^G$5 -> 11192.263 | H20: =$D20*(1+$C20)^H$5 -> 11092.652 | I20: =$D20*(1+$C20)^I$5 -> 10993.927 | J20: =$D20*(1+$C20)^J$5 -> 10896.081 | K20: =$D20*(1+$C20)^K$5 -> 10799.106 | L20: =$D20*(1+$C20)^L$5 -> 10702.994 | ... N20: =$D20*(1+$C20)^N$5 -> 10513.328 | O20: =AVERAGE(E20:N20) -> 10948.503 | P20: y+0에 현재 유가·환율 배율이 이미 반영됨 — 성장률은 그 위에 매년 복리 (레벨 shift vs 연간 변화율, 이중 반영 아님)
B21: · 항비 | C21: =설정값!$D$80 -> 0.0785 | D21: =대조선박_손익!$C$61/1000000 -> 960.34745 | E21: =$D21*(1+$C21)^E$5 -> 1035.7347 | F21: =$D21*(1+$C21)^F$5 -> 1117.0399 | G21: =$D21*(1+$C21)^G$5 -> 1204.7275 | H21: =$D21*(1+$C21)^H$5 -> 1299.2986 | I21: =$D21*(1+$C21)^I$5 -> 1401.2936 | J21: =$D21*(1+$C21)^J$5 -> 1511.2951 | K21: =$D21*(1+$C21)^K$5 -> 1629.9318 | L21: =$D21*(1+$C21)^L$5 -> 1757.8815 | ... N21: =$D21*(1+$C21)^N$5 -> 2044.7013 | O21: =AVERAGE(E21:N21) -> 1489.7779
B22: · 보험료 | C22: =설정값!$D$81 -> 0.0382 | D22: =대조선박_손익!$C$62/1000000 -> 441.84596 | E22: =$D22*(1+$C22)^E$5 -> 458.72447 | F22: =$D22*(1+$C22)^F$5 -> 476.24775 | G22: =$D22*(1+$C22)^G$5 -> 494.44041 | H22: =$D22*(1+$C22)^H$5 -> 513.32804 | I22: =$D22*(1+$C22)^I$5 -> 532.93717 | J22: =$D22*(1+$C22)^J$5 -> 553.29537 | K22: =$D22*(1+$C22)^K$5 -> 574.43125 | L22: =$D22*(1+$C22)^L$5 -> 596.37452 | ... N22: =$D22*(1+$C22)^N$5 -> 642.80779 | O22: =AVERAGE(E22:N22) -> 546.17428
B23: · 수리비 (10년 전용) | C23: =설정값!$D$82 -> 0.05 | D23: =설정값!$D$105 -> 700 | E23: =$D23*(1+$C23)^E$5 -> 735 | F23: =$D23*(1+$C23)^F$5 -> 771.75 | G23: =$D23*(1+$C23)^G$5 -> 810.3375 | H23: =$D23*(1+$C23)^H$5 -> 850.85438 | I23: =$D23*(1+$C23)^I$5 -> 893.39709 | J23: =$D23*(1+$C23)^J$5 -> 938.06695 | K23: =$D23*(1+$C23)^K$5 -> 984.9703 | L23: =$D23*(1+$C23)^L$5 -> 1034.2188 | ... N23: =$D23*(1+$C23)^N$5 -> 1140.2262 | O23: =AVERAGE(E23:N23) -> 924.4751
B24: · 선용품비 | C24: =설정값!$D$83 -> 0.15 | D24: =대조선박_손익!$C$64/1000000 -> 23.25505 | E24: =$D24*(1+$C24)^E$5 -> 26.743308 | F24: =$D24*(1+$C24)^F$5 -> 30.754804 | G24: =$D24*(1+$C24)^G$5 -> 35.368025 | H24: =$D24*(1+$C24)^H$5 -> 40.673228 | I24: =$D24*(1+$C24)^I$5 -> 46.774213 | J24: =$D24*(1+$C24)^J$5 -> 53.790345 | K24: =$D24*(1+$C24)^K$5 -> 61.858896 | L24: =$D24*(1+$C24)^L$5 -> 71.137731 | ... N24: =$D24*(1+$C24)^N$5 -> 94.079649 | O24: =AVERAGE(E24:N24) -> 54.298859
B25: 선체이자 | D25: =차입금_상환!$E$20/1000000 -> 700 | E25: =차입금_상환!$E$21/1000000 -> 700 | F25: =차입금_상환!$E$22/1000000 -> 700 | G25: =차입금_상환!$E$23/1000000 -> 700 | H25: =차입금_상환!$E$24/1000000 -> 641.66667 | I25: =차입금_상환!$E$25/1000000 -> 583.33333 | J25: =차입금_상환!$E$26/1000000 -> 525 | K25: =차입금_상환!$E$27/1000000 -> 466.66667 | L25: =차입금_상환!$E$28/1000000 -> 408.33333 | M25: =차입금_상환!$E$29/1000000 -> 350 | N25: =차입금_상환!$E$30/1000000 -> 291.66667 | O25: =AVERAGE(E25:N25) -> 536.66667 | P25: 차입금_상환 시트 연도별 이자 — 성장률 미적용. 우리 회사는 선박 차입 이자를 운항원가 "선체이자"로 넣는다 (단일연도 표에서는 영업외비용)
B26: Ⅲ. 매출총이익 | D26: =D7+-D12 -> 6929.5317 | E26: =E7+-E12 -> 7465.6185 | F26: =F7+-F12 -> 8007.0214 | G26: =G7+-G12 -> 8553.4967 | H26: =H7+-H12 -> 9163.0915 | I26: =I7+-I12 -> 9777.1388 | J26: =J7+-J12 -> 10395.252 | K26: =K7+-K12 -> 11016.988 | ... N26: =N7+-N12 -> 12898.474 | O26: =AVERAGE(E26:N26) -> 10118.813
B27: Ⅳ. 판매비와관리비 | D27: =D28++D29++D30++D31++D32++D33 -> 3121.0125 | E27: =E28++E29++E30++E31++E32++E33 -> 3266.2223 | F27: =F28++F29++F30++F31++F32++F33 -> 3418.8926 | G27: =G28++G29++G30++G31++G32++G33 -> 3579.4276 | H27: =H28++H29++H30++H31++H32++H33 -> 3748.2542 | I27: =I28++I29++I30++I31++I32++I33 -> 3925.8228 | J27: =J28++J29++J30++J31++J32++J33 -> 4112.609 | K27: =K28++K29++K30++K31++K32++K33 -> 4309.115 | ... N27: =N28++N29++N30++N31++N32++N33 -> 4962.4019 | O27: =AVERAGE(E27:N27) -> 4057.2052
B28: 직원급여 (육상직원) | C28: =설정값!$D$84 -> 0.0568 | D28: =대조선박_손익!$C$67/1000000 -> 1822.8787 | E28: =$D28*(1+$C28)^E$5 -> 1926.4182 | F28: =$D28*(1+$C28)^F$5 -> 2035.8387 | G28: =$D28*(1+$C28)^G$5 -> 2151.4743 | H28: =$D28*(1+$C28)^H$5 -> 2273.6781 | I28: =$D28*(1+$C28)^I$5 -> 2402.823 | J28: =$D28*(1+$C28)^J$5 -> 2539.3034 | K28: =$D28*(1+$C28)^K$5 -> 2683.5358 | L28: =$D28*(1+$C28)^L$5 -> 2835.9606 | ... N28: =$D28*(1+$C28)^N$5 -> 3167.2752 | O28: =AVERAGE(E28:N28) -> 2501.335
B29: 퇴직급여 (육상직원) | C29: =설정값!$D$84 -> 0.0568 | D29: =대조선박_손익!$C$68/1000000 -> 152.42019 | E29: =$D29*(1+$C29)^E$5 -> 161.07766 | F29: =$D29*(1+$C29)^F$5 -> 170.22687 | G29: =$D29*(1+$C29)^G$5 -> 179.89576 | H29: =$D29*(1+$C29)^H$5 -> 190.11384 | I29: =$D29*(1+$C29)^I$5 -> 200.9123 | J29: =$D29*(1+$C29)^J$5 -> 212.32412 | K29: =$D29*(1+$C29)^K$5 -> 224.38413 | L29: =$D29*(1+$C29)^L$5 -> 237.12915 | ... N29: =$D29*(1+$C29)^N$5 -> 264.83206 | O29: =AVERAGE(E29:N29) -> 209.1494
B30: 복리후생비 (육상직원) | C30: =설정값!$D$84 -> 0.0568 | D30: =대조선박_손익!$C$69/1000000 -> 147.55341 | E30: =$D30*(1+$C30)^E$5 -> 155.93444 | F30: =$D30*(1+$C30)^F$5 -> 164.79152 | G30: =$D30*(1+$C30)^G$5 -> 174.15167 | H30: =$D30*(1+$C30)^H$5 -> 184.04349 | I30: =$D30*(1+$C30)^I$5 -> 194.49716 | J30: =$D30*(1+$C30)^J$5 -> 205.5446 | K30: =$D30*(1+$C30)^K$5 -> 217.21953 | L30: =$D30*(1+$C30)^L$5 -> 229.5576 | ... N30: =$D30*(1+$C30)^N$5 -> 256.37595 | O30: =AVERAGE(E30:N30) -> 202.47124
B31: 세금과공과 | C31: =설정값!$D$85 -> 0.0292 | D31: =대조선박_손익!$C$70/1000000 -> 62.9715 | E31: =$D31*(1+$C31)^E$5 -> 64.810268 | F31: =$D31*(1+$C31)^F$5 -> 66.702728 | G31: =$D31*(1+$C31)^G$5 -> 68.650447 | H31: =$D31*(1+$C31)^H$5 -> 70.65504 | I31: =$D31*(1+$C31)^I$5 -> 72.718168 | J31: =$D31*(1+$C31)^J$5 -> 74.841538 | K31: =$D31*(1+$C31)^K$5 -> 77.026911 | L31: =$D31*(1+$C31)^L$5 -> 79.276097 | ... N31: =$D31*(1+$C31)^N$5 -> 83.973415 | O31: =AVERAGE(E31:N31) -> 74.024557
B32: 지급수수료 | C32: =설정값!$D$86 -> 0.0234 | D32: =대조선박_손익!$C$71/1000000 -> 682.5102 | E32: =$D32*(1+$C32)^E$5 -> 698.48094 | F32: =$D32*(1+$C32)^F$5 -> 714.82539 | G32: =$D32*(1+$C32)^G$5 -> 731.55231 | H32: =$D32*(1+$C32)^H$5 -> 748.67063 | I32: =$D32*(1+$C32)^I$5 -> 766.18952 | J32: =$D32*(1+$C32)^J$5 -> 784.11836 | K32: =$D32*(1+$C32)^K$5 -> 802.46673 | L32: =$D32*(1+$C32)^L$5 -> 821.24445 | ... N32: =$D32*(1+$C32)^N$5 -> 860.12837 | O32: =AVERAGE(E32:N32) -> 776.81383
B33: 그 외 (세금과공과·지급수수료 제외) | D33: =D34++D35++D36++D37++D38++D39++D40++D41++D42++D43++D44++D45++D46++D47 -> 252.67856 | E33: =E34++E35++E36++E37++E38++E39++E40++E41++E42++E43++E44++E45++E46++E47 -> 259.50088 | F33: =F34++F35++F36++F37++F38++F39++F40++F41++F42++F43++F44++F45++F46++F47 -> 266.50741 | G33: =G34++G35++G36++G37++G38++G39++G40++G41++G42++G43++G44++G45++G46++G47 -> 273.70311 | H33: =H34++H35++H36++H37++H38++H39++H40++H41++H42++H43++H44++H45++H46++H47 -> 281.09309 | I33: =I34++I35++I36++I37++I38++I39++I40++I41++I42++I43++I44++I45++I46++I47 -> 288.6826 | J33: =J34++J35++J36++J37++J38++J39++J40++J41++J42++J43++J44++J45++J46++J47 -> 296.47703 | K33: =K34++K35++K36++K37++K38++K39++K40++K41++K42++K43++K44++K45++K46++K47 -> 304.48191 | ... N33: =N34++N35++N36++N37++N38++N39++N40++N41++N42++N43++N44++N45++N46++N47 -> 329.81684 | O33: =AVERAGE(E33:N33) -> 293.41117
B34: · 여비교통비 | C34: =설정값!$D$87 -> 0.027 | D34: =대조선박_손익!$C$73/1000000 -> 9.246562 | E34: =$D34*(1+$C34)^E$5 -> 9.4962192 | F34: =$D34*(1+$C34)^F$5 -> 9.7526171 | G34: =$D34*(1+$C34)^G$5 -> 10.015938 | H34: =$D34*(1+$C34)^H$5 -> 10.286368 | I34: =$D34*(1+$C34)^I$5 -> 10.5641 | J34: =$D34*(1+$C34)^J$5 -> 10.849331 | K34: =$D34*(1+$C34)^K$5 -> 11.142263 | L34: =$D34*(1+$C34)^L$5 -> 11.443104 | ... N34: =$D34*(1+$C34)^N$5 -> 12.069373 | O34: =AVERAGE(E34:N34) -> 10.737138
B35: · 접대비 | C35: =설정값!$D$87 -> 0.027 | D35: =대조선박_손익!$C$74/1000000 -> 8.802 | E35: =$D35*(1+$C35)^E$5 -> 9.039654 | F35: =$D35*(1+$C35)^F$5 -> 9.2837247 | G35: =$D35*(1+$C35)^G$5 -> 9.5343852 | H35: =$D35*(1+$C35)^H$5 -> 9.7918136 | I35: =$D35*(1+$C35)^I$5 -> 10.056193 | J35: =$D35*(1+$C35)^J$5 -> 10.32771 | K35: =$D35*(1+$C35)^K$5 -> 10.606558 | L35: =$D35*(1+$C35)^L$5 -> 10.892935 | ... N35: =$D35*(1+$C35)^N$5 -> 11.489094 | O35: =AVERAGE(E35:N35) -> 10.220911
B36: · 통신비 | C36: =설정값!$D$87 -> 0.027 | D36: =대조선박_손익!$C$75/1000000 -> 9.364469 | E36: =$D36*(1+$C36)^E$5 -> 9.6173097 | F36: =$D36*(1+$C36)^F$5 -> 9.876977 | G36: =$D36*(1+$C36)^G$5 -> 10.143655 | H36: =$D36*(1+$C36)^H$5 -> 10.417534 | I36: =$D36*(1+$C36)^I$5 -> 10.698808 | J36: =$D36*(1+$C36)^J$5 -> 10.987675 | K36: =$D36*(1+$C36)^K$5 -> 11.284343 | L36: =$D36*(1+$C36)^L$5 -> 11.58902 | ... N36: =$D36*(1+$C36)^N$5 -> 12.223275 | O36: =AVERAGE(E36:N36) -> 10.874052
B37: · 수도광열비 | C37: =설정값!$D$87 -> 0.027 | D37: =대조선박_손익!$C$76/1000000 -> 16.446116 | E37: =$D37*(1+$C37)^E$5 -> 16.890161 | F37: =$D37*(1+$C37)^F$5 -> 17.346195 | G37: =$D37*(1+$C37)^G$5 -> 17.814543 | H37: =$D37*(1+$C37)^H$5 -> 18.295535 | I37: =$D37*(1+$C37)^I$5 -> 18.789515 | J37: =$D37*(1+$C37)^J$5 -> 19.296832 | K37: =$D37*(1+$C37)^K$5 -> 19.817846 | L37: =$D37*(1+$C37)^L$5 -> 20.352928 | ... N37: =$D37*(1+$C37)^N$5 -> 21.466823 | O37: =AVERAGE(E37:N37) -> 19.097284
B38: · 지급임차료 | C38: =설정값!$D$87 -> 0.027 | D38: =대조선박_손익!$C$77/1000000 -> 74.136257 | E38: =$D38*(1+$C38)^E$5 -> 76.137936 | F38: =$D38*(1+$C38)^F$5 -> 78.19366 | G38: =$D38*(1+$C38)^G$5 -> 80.304889 | H38: =$D38*(1+$C38)^H$5 -> 82.473121 | I38: =$D38*(1+$C38)^I$5 -> 84.699895 | J38: =$D38*(1+$C38)^J$5 -> 86.986792 | K38: =$D38*(1+$C38)^K$5 -> 89.335436 | L38: =$D38*(1+$C38)^L$5 -> 91.747493 | ... N38: =$D38*(1+$C38)^N$5 -> 96.768741 | O38: =AVERAGE(E38:N38) -> 86.087264
B39: · 수선비 | C39: =설정값!$D$87 -> 0.027 | D39: =대조선박_손익!$C$78/1000000 -> 0 | E39: =$D39*(1+$C39)^E$5 -> 0 | F39: =$D39*(1+$C39)^F$5 -> 0 | G39: =$D39*(1+$C39)^G$5 -> 0 | H39: =$D39*(1+$C39)^H$5 -> 0 | I39: =$D39*(1+$C39)^I$5 -> 0 | J39: =$D39*(1+$C39)^J$5 -> 0 | K39: =$D39*(1+$C39)^K$5 -> 0 | L39: =$D39*(1+$C39)^L$5 -> 0 | ... N39: =$D39*(1+$C39)^N$5 -> 0 | O39: =AVERAGE(E39:N39) -> 0
B40: · 보험료 | C40: =설정값!$D$87 -> 0.027 | D40: =대조선박_손익!$C$79/1000000 -> 7.359767 | E40: =$D40*(1+$C40)^E$5 -> 7.5584807 | F40: =$D40*(1+$C40)^F$5 -> 7.7625597 | G40: =$D40*(1+$C40)^G$5 -> 7.9721488 | H40: =$D40*(1+$C40)^H$5 -> 8.1873968 | I40: =$D40*(1+$C40)^I$5 -> 8.4084565 | J40: =$D40*(1+$C40)^J$5 -> 8.6354849 | K40: =$D40*(1+$C40)^K$5 -> 8.8686429 | L40: =$D40*(1+$C40)^L$5 -> 9.1080963 | ... N40: =$D40*(1+$C40)^N$5 -> 9.6065733 | O40: =AVERAGE(E40:N40) -> 8.5461855
B41: · 차량유지비 | C41: =설정값!$D$87 -> 0.027 | D41: =대조선박_손익!$C$80/1000000 -> 0.509 | E41: =$D41*(1+$C41)^E$5 -> 0.522743 | F41: =$D41*(1+$C41)^F$5 -> 0.53685706 | G41: =$D41*(1+$C41)^G$5 -> 0.5513522 | H41: =$D41*(1+$C41)^H$5 -> 0.56623871 | I41: =$D41*(1+$C41)^I$5 -> 0.58152716 | J41: =$D41*(1+$C41)^J$5 -> 0.59722839 | K41: =$D41*(1+$C41)^K$5 -> 0.61335356 | L41: =$D41*(1+$C41)^L$5 -> 0.6299141 | ... N41: =$D41*(1+$C41)^N$5 -> 0.66438867 | O41: =AVERAGE(E41:N41) -> 0.59105246
B42: · 운반비 | C42: =설정값!$D$87 -> 0.027 | D42: =대조선박_손익!$C$81/1000000 -> 0.51385 | E42: =$D42*(1+$C42)^E$5 -> 0.52772395 | F42: =$D42*(1+$C42)^F$5 -> 0.5419725 | G42: =$D42*(1+$C42)^G$5 -> 0.55660575 | H42: =$D42*(1+$C42)^H$5 -> 0.57163411 | I42: =$D42*(1+$C42)^I$5 -> 0.58706823 | J42: =$D42*(1+$C42)^J$5 -> 0.60291907 | K42: =$D42*(1+$C42)^K$5 -> 0.61919789 | L42: =$D42*(1+$C42)^L$5 -> 0.63591623 | ... N42: =$D42*(1+$C42)^N$5 -> 0.67071929 | O42: =AVERAGE(E42:N42) -> 0.5966843
...

Sheet 목표이익률_지표
B1: 목표 영업이익률 도달 지표 — 참조(대저페리 3기) · 대조 선박
B2: 영업이익 = (P·Q + O) − (F + SV/항차·항차(Q) + v·Q) · 목표 r 을 만족하는 Q = (F + SV·항차 − (1−r)·O) ÷ ((1−r)·P − v)
B4: A. 참조 — 대저페리 제3기 원가 구조 (엘도라도 익스프레스호)
B5: 모형 입력 | C5: 값 | D5: 근거
B6: 고정비 F | C6: =원가구조_기준!$F$68 -> 7536536311 | D6: 원가구조_기준 5
B7: 준변동비 SV | C7: =원가구조_기준!$G$68 -> 7148774749 | D7: 항차에 비례
B8: 설정 항차 | C8: =설정값!$D$11 -> 498
B9: 실현 단가 P | C9: =원가구조_기준!$C$44 -> 88950
B10: 승객 1인 변동비 v | C10: =원가구조_기준!$C$74 -> 3754.1815
B11: 여객 외 수입 O | C11: =원가구조_기준!$C$8 -> 332642171 | D11: 화물 + 임대료 (실적)
B12: 정원 | C12: =원가구조_기준!$C$47 -> 970 | D12: 엘도라도
B13: 항차 자동 증가 | C13: =설정값!$D$18 -> X
B14: 현재 승객수 | C14: =원가구조_기준!$C$46 -> 158197 | D14: 시뮬레이션 승객수
B15: 비교 기준 승객수 | C15: =원가구조_기준!$C$45 -> 144058.09 | D15: 실적 역산
B16: 변동비 환산 분모 | C16: =원가구조_기준!$C$45 -> 144058.09 | D16: 실적 역산 (공통)
B17: 수동 추가 변동비 | C17: =설정값!$D$17 -> 0
B18: 목표 영업이익률 | C18: =설정값!$D$19 -> 0.15
B19: 운항원가 — 고정 | C19: =원가구조_기준!$F$69 -> 5098034000
B20: 운항원가 — 준변동 | C20: =원가구조_기준!$G$69 -> 7148774749
B21: 운항원가 — 변동 | C21: =원가구조_기준!$H$69 -> 0
B22: 판관비 — 고정 | C22: =원가구조_기준!$F$70 -> 2438502311
B23: 판관비 — 준변동 | C23: =원가구조_기준!$G$70 -> 0
B24: 판관비 — 변동 | C24: =원가구조_기준!$H$70 -> 540820215
B25: 전사 인건비 | C25: =원가구조_기준!$C$20+원가구조_기준!$C$34 -> 3792443250 | D25: 운항 인건비 + 판관 급여영역
B26: 현재 설정 승객수에서
B27: 항목 | C27: 값
B28: 적용 항차 | C28: =IF(AND($C$13="O",$C$12>0),MAX($C$8,CEILING(($C$14)/$C$12,1)),$C$8) -> 498
B29: 매출액 | C29: =$C$14*$C$9+$C$11 -> 14404265321
B30: 총비용 | C30: =($C$6+$C$7/$C$8*(IF(AND($C$13="O",$C$12>0),MAX($C$8,CEILING(($C$14)/$C$12,1)),$C$8))+$C$10*($C$14)) -> 1.5279211e+10
B31: 영업이익 | C31: =$C$29-$C$30 -> -8.7494599e+08
B32: 영업이익률 | C32: =IFERROR($C$31/$C$29,0) -> -0.060742146
Q33: 반복계산 보조 — "항차 자동 증가"가 O일 때 승객수가 항차를 밀어 올리면 다시 푼다 ( qFor 과 같은 절차)
B34: 목표 영업이익률 | C34: 필요 승객수 | D34: 실적 대비(명) | E34: 필요 운임 (현재 승객 고정) | F34: 항차당 승객 | G34: 적용 항차 | H34: 승선율 | I34: 매출액 | J34: 운항원가 | K34: 운항원가율 | L34: 판관비 | M34: 판관비율 | N34: 전사 인건비율 | O34: 영업이익률 (검증) | P34: 필요 승객수 — 화물 제외 | Q34: 분모 (1−r)P−v | R34: 항차0 | S34: Q0 | T34: 항차1 | U34: Q1 | V34: 항차2 | W34: Q2 | X34: 항차3 | Y34: Q3
B35: 0 | C35: =IF($Q35<=0,"달성 불가",Y35) -> 168466.82 | D35: =IF(ISNUMBER(C35),C35-$C$15,"") -> 24408.734 | E35: =IFERROR((($C$6+$C$7/$C$8*IF(AND($C$13="O",$C$12>0),MAX($C$8,CEILING(($C$14)/$C$12,1)),$C$8)+$C$10*$C$14)/(1-$B35)-$C$11)/$C$14,"") -> 94480.737 | F35: =IF(ISNUMBER(C35),C35/$C$8,"") -> 338.28679 | G35: =IF(ISNUMBER(C35),IF(AND($C$13="O",$C$12>0),MAX($C$8,CEILING((C35)/$C$12,1)),$C$8),"") -> 498 | H35: =IF(AND(ISNUMBER(C35),$C$12>0),C35/($C$12*$C$8),"") -> 0.34874927 | I35: =IF(ISNUMBER(C35),C35*$C$9+$C$11,"") -> 1.5317766e+10 | J35: =IF(ISNUMBER(C35),$C$19+$C$20/$C$8*G35+$C$21/$C$16*C35+$C$17*C35,"") -> 12246808749 | K35: =IF(ISNUMBER(C35),J35/I35,"") -> 0.79951663 | L35: =IF(ISNUMBER(C35),$C$22+$C$23/$C$8*G35+$C$24/$C$16*C35,"") -> 3.0709573e+09 | M35: =IF(ISNUMBER(C35),L35/I35,"") -> 0.20048337 | N35: =IF(ISNUMBER(C35),$C$25/I35,"") -> 0.24758462 | O35: =IF(ISNUMBER(C35),(I35-J35-L35)/I35,"") -> 3.112968e-17 | P35: =IF($Q35<=0,"달성 불가",MAX(0,($C$6+$C$7/$C$8*X35-(1-$B35)*($C$11-원가구조_기준!$C$9))/$Q35)) -> 172258.58 | Q35: =(1-$B35)*$C$9-$C$10 -> 85195.818 | R35: =$C$8 -> 498 | S35: =IF($Q35<=0,0,MAX(0,($C$6+$C$7/$C$8*R35-(1-$B35)*$C$11)/$Q35)) -> 168466.82 | T35: =IF(AND($C$13="O",$C$12>0),MAX($C$8,CEILING((S35)/$C$12,1)),$C$8) -> 498 | U35: =IF($Q35<=0,0,MAX(0,($C$6+$C$7/$C$8*T35-(1-$B35)*$C$11)/$Q35)) -> 168466.82 | V35: =IF(AND($C$13="O",$C$12>0),MAX($C$8,CEILING((U35)/$C$12,1)),$C$8) -> 498 | W35: =IF($Q35<=0,0,MAX(0,($C$6+$C$7/$C$8*V35-(1-$B35)*$C$11)/$Q35)) -> 168466.82 | X35: =IF(AND($C$13="O",$C$12>0),MAX($C$8,CEILING((W35)/$C$12,1)),$C$8) -> 498 | Y35: =IF($Q35<=0,0,MAX(0,($C$6+$C$7/$C$8*X35-(1-$B35)*$C$11)/$Q35)) -> 168466.82
B36: 0.03 | C36: =IF($Q36<=0,"달성 불가",Y36) -> 174035.08 | D36: =IF(ISNUMBER(C36),C36-$C$15,"") -> 29976.987 | E36: =IFERROR((($C$6+$C$7/$C$8*IF(AND($C$13="O",$C$12>0),MAX($C$8,CEILING(($C$14)/$C$12,1)),$C$8)+$C$10*$C$14)/(1-$B36)-$C$11)/$C$14,"") -> 97467.854 | F36: =IF(ISNUMBER(C36),C36/$C$8,"") -> 349.46802 | G36: =IF(ISNUMBER(C36),IF(AND($C$13="O",$C$12>0),MAX($C$8,CEILING((C36)/$C$12,1)),$C$8),"") -> 498 | H36: =IF(AND(ISNUMBER(C36),$C$12>0),C36/($C$12*$C$8),"") -> 0.36027631 | I36: =IF(ISNUMBER(C36),C36*$C$9+$C$11,"") -> 1.5813062e+10 | J36: =IF(ISNUMBER(C36),$C$19+$C$20/$C$8*G36+$C$21/$C$16*C36+$C$17*C36,"") -> 12246808749 | K36: =IF(ISNUMBER(C36),J36/I36,"") -> 0.7744742 | L36: =IF(ISNUMBER(C36),$C$22+$C$23/$C$8*G36+$C$24/$C$16*C36,"") -> 3.0918616e+09 | M36: =IF(ISNUMBER(C36),L36/I36,"") -> 0.1955258 | N36: =IF(ISNUMBER(C36),$C$25/I36,"") -> 0.23982978 | O36: =IF(ISNUMBER(C36),(I36-J36-L36)/I36,"") -> 0.03 | P36: =IF($Q36<=0,"달성 불가",MAX(0,($C$6+$C$7/$C$8*X36-(1-$B36)*($C$11-원가구조_기준!$C$9))/$Q36)) -> 177832.01 | Q36: =(1-$B36)*$C$9-$C$10 -> 82527.318 | R36: =$C$8 -> 498 | S36: =IF($Q36<=0,0,MAX(0,($C$6+$C$7/$C$8*R36-(1-$B36)*$C$11)/$Q36)) -> 174035.08 | T36: =IF(AND($C$13="O",$C$12>0),MAX($C$8,CEILING((S36)/$C$12,1)),$C$8) -> 498 | U36: =IF($Q36<=0,0,MAX(0,($C$6+$C$7/$C$8*T36-(1-$B36)*$C$11)/$Q36)) -> 174035.08 | V36: =IF(AND($C$13="O",$C$12>0),MAX($C$8,CEILING((U36)/$C$12,1)),$C$8) -> 498 | W36: =IF($Q36<=0,0,MAX(0,($C$6+$C$7/$C$8*V36-(1-$B36)*$C$11)/$Q36)) -> 174035.08 | X36: =IF(AND($C$13="O",$C$12>0),MAX($C$8,CEILING((W36)/$C$12,1)),$C$8) -> 498 | Y36: =IF($Q36<=0,0,MAX(0,($C$6+$C$7/$C$8*X36-(1-$B36)*$C$11)/$Q36)) -> 174035.08
B37: 0.05 | C37: =IF($Q37<=0,"달성 불가",Y37) -> 177951.71 | D37: =IF(ISNUMBER(C37),C37-$C$15,"") -> 33893.617 | E37: =IFERROR((($C$6+$C$7/$C$8*IF(AND($C$13="O",$C$12>0),MAX($C$8,CEILING(($C$14)/$C$12,1)),$C$8)+$C$10*$C$14)/(1-$B37)-$C$11)/$C$14,"") -> 99564.076 | F37: =IF(ISNUMBER(C37),C37/$C$8,"") -> 357.33274 | G37: =IF(ISNUMBER(C37),IF(AND($C$13="O",$C$12>0),MAX($C$8,CEILING((C37)/$C$12,1)),$C$8),"") -> 498 | H37: =IF(AND(ISNUMBER(C37),$C$12>0),C37/($C$12*$C$8),"") -> 0.36838427 | I37: =IF(ISNUMBER(C37),C37*$C$9+$C$11,"") -> 1.6161446e+10 | J37: =IF(ISNUMBER(C37),$C$19+$C$20/$C$8*G37+$C$21/$C$16*C37+$C$17*C37,"") -> 12246808749 | K37: =IF(ISNUMBER(C37),J37/I37,"") -> 0.75777925 | L37: =IF(ISNUMBER(C37),$C$22+$C$23/$C$8*G37+$C$24/$C$16*C37,"") -> 3.1065653e+09 | M37: =IF(ISNUMBER(C37),L37/I37,"") -> 0.19222075 | N37: =IF(ISNUMBER(C37),$C$25/I37,"") -> 0.23465989 | O37: =IF(ISNUMBER(C37),(I37-J37-L37)/I37,"") -> 0.05 | P37: =IF($Q37<=0,"달성 불가",MAX(0,($C$6+$C$7/$C$8*X37-(1-$B37)*($C$11-원가구조_기준!$C$9))/$Q37)) -> 181752.28 | Q37: =(1-$B37)*$C$9-$C$10 -> 80748.318 | R37: =$C$8 -> 498 | S37: =IF($Q37<=0,0,MAX(0,($C$6+$C$7/$C$8*R37-(1-$B37)*$C$11)/$Q37)) -> 177951.71 | T37: =IF(AND($C$13="O",$C$12>0),MAX($C$8,CEILING((S37)/$C$12,1)),$C$8) -> 498 | U37: =IF($Q37<=0,0,MAX(0,($C$6+$C$7/$C$8*T37-(1-$B37)*$C$11)/$Q37)) -> 177951.71 | V37: =IF(AND($C$13="O",$C$12>0),MAX($C$8,CEILING((U37)/$C$12,1)),$C$8) -> 498 | W37: =IF($Q37<=0,0,MAX(0,($C$6+$C$7/$C$8*V37-(1-$B37)*$C$11)/$Q37)) -> 177951.71 | X37: =IF(AND($C$13="O",$C$12>0),MAX($C$8,CEILING((W37)/$C$12,1)),$C$8) -> 498 | Y37: =IF($Q37<=0,0,MAX(0,($C$6+$C$7/$C$8*X37-(1-$B37)*$C$11)/$Q37)) -> 177951.71
